Workbook

Sheet Instructions
A1: Masters Draft Scoring Workbook
A3: Step | B3: What to do
A4: 1 | B4: From your draft webpage, export the finished draft board to CSV.
A5: 2 | B5: Open the CSV, copy everything, and paste it into the Draft_Import sheet starting in cell A1. You can paste the header row too.
A6: 3 | B6: Go to the Team_Scoring sheet. Each team roster will fill in automatically based on the Team and Player columns from the pasted draft.
A7: 5 | B7: The Numeric column converts E or (E) into 0 automatically.
A8: 6 | B8: On Team Scoring - Each team's Best 4 Total adds the four lowest numeric scores currently entered for that team.
A9: 7 | B9: The Team_Summary sheet shows every team's live total in one place.
A12: Examples
A13: Entered score | B13: Numeric result
A14: E | B14: 0
A15: (E) | B15: 0
A16: -4 | B16: -4
A17: +3 | B17: 3
A18: 0 | B18: 0

Sheet Draft_Import
A1: Round | B1: Pick In Round | C1: Overall Pick | D1: Team | E1: Player
A2: 1 | B2: 1 | C2: 1 | D2: Ross | E2: Scottie Scheffler
A3: 1 | B3: 2 | C3: 2 | D3: Melbye² | E3: Bryson DeChambeau
A4: 1 | B4: 3 | C4: 3 | D4: Bryan | E4: Jon Rahm
A5: 1 | B5: 4 | C5: 4 | D5: Dan 'Full Swing' Clark | E5: Ludvig Åberg
A6: 1 | B6: 5 | C6: 5 | D6: Roth | E6: Rory McIlroy
A7: 1 | B7: 6 | C7: 6 | D7: Coulter | E7: Xander Schauffele
A8: 1 | B8: 7 | C8: 7 | D8: Klooster | E8: Justin Rose
A9: 1 | B9: 8 | C9: 8 | D9: Adam & Kevin | E9: Cameron Young
A10: 1 | B10: 9 | C10: 9 | D10: Asshole Garrett | E10: Collin Morikawa
A11: 1 | B11: 10 | C11: 10 | D11: Cool Tony | E11: Tommy Fleetwood
A12: 2 | B12: 1 | C12: 11 | D12: Cool Tony | E12: Matt Fitzpatrick
A13: 2 | B13: 2 | C13: 12 | D13: Asshole Garrett | E13: Min Woo Lee
... A92: 10 | B92: 1 | C92: 91 | D92: Cool Tony | E92: Sergio Garcia

Sheet Draft_Helper
A1: =IF(Draft_Import!D2<>"",Draft_Import!D2,"Team 1") | C1: =IF(Draft_Import!D3<>"",Draft_Import!D3,"Team 2") | E1: =IF(Draft_Import!D4<>"",Draft_Import!D4,"Team 3") | G1: =IF(Draft_Import!D5<>"",Draft_Import!D5,"Team 4") | I1: =IF(Draft_Import!D6<>"",Draft_Import!D6,"Team 5") | K1: =IF(Draft_Import!D7<>"",Draft_Import!D7,"Team 6") | M1: =IF(Draft_Import!D8<>"",Draft_Import!D8,"Team 7") | O1: =IF(Draft_Import!D9<>"",Draft_Import!D9,"Team 8") | Q1: =IF(Draft_Import!D10<>"",Draft_Import!D10,"Team 9") | S1: =IF(Draft_Import!D11<>"",Draft_Import!D11,"Team 10")
A2: =IF(Draft_Import!$D2=A$1,COUNTIF(Draft_Import!$D$2:'Draft_Import'!$D2,A$1),"") | B2: =IFERROR(INDEX(Draft_Import!$E$2:$E$250,MATCH(ROWS(B$2:B2),A$2:A$250,0)),"") | C2: =IF(Draft_Import!$D2=C$1,COUNTIF(Draft_Import!$D$2:'Draft_Import'!$D2,C$1),"") | D2: =IFERROR(INDEX(Draft_Import!$E$2:$E$250,MATCH(ROWS(D$2:D2),C$2:C$250,0)),"") | E2: =IF(Draft_Import!$D2=E$1,COUNTIF(Draft_Import!$D$2:'Draft_Import'!$D2,E$1),"") | F2: =IFERROR(INDEX(Draft_Import!$E$2:$E$250,MATCH(ROWS(F$2:F2),E$2:E$250,0)),"") | G2: =IF(Draft_Import!$D2=G$1,COUNTIF(Draft_Import!$D$2:'Draft_Import'!$D2,G$1),"") | H2: =IFERROR(INDEX(Draft_Import!$E$2:$E$250,MATCH(ROWS(H$2:H2),G$2:G$250,0)),"") | I2: =IF(Draft_Import!$D2=I$1,COUNTIF(Draft_Import!$D$2:'Draft_Import'!$D2,I$1),"") | J2: =IFERROR(INDEX(Draft_Import!$E$2:$E$250,MATCH(ROWS(J$2:J2),I$2:I$250,0)),"") | K2: =IF(Draft_Import!$D2=K$1,COUNTIF(Draft_Import!$D$2:'Draft_Import'!$D2,K$1),"") | L2: =IFERROR(INDEX(Draft_Import!$E$2:$E$250,MATCH(ROWS(L$2:L2),K$2:K$250,0)),"") | M2: =IF(Draft_Import!$D2=M$1,COUNTIF(Draft_Import!$D$2:'Draft_Import'!$D2,M$1),"") | N2: =IFERROR(INDEX(Draft_Import!$E$2:$E$250,MATCH(ROWS(N$2:N2),M$2:M$250,0)),"") | O2: =IF(Draft_Import!$D2=O$1,COUNTIF(Draft_Import!$D$2:'Draft_Import'!$D2,O$1),"") | P2: =IFERROR(INDEX(Draft_Import!$E$2:$E$250,MATCH(ROWS(P$2:P2),O$2:O$250,0)),"") | Q2: =IF(Draft_Import!$D2=Q$1,COUNTIF(Draft_Import!$D$2:'Draft_Import'!$D2,Q$1),"") | R2: =IFERROR(INDEX(Draft_Import!$E$2:$E$250,MATCH(ROWS(R$2:R2),Q$2:Q$250,0)),"") | S2: =IF(Draft_Import!$D2=S$1,COUNTIF(Draft_Import!$D$2:'Draft_Import'!$D2,S$1),"") | T2: =IFERROR(INDEX(Draft_Import!$E$2:$E$250,MATCH(ROWS(T$2:T2),S$2:S$250,0)),"")
A3: =IF(Draft_Import!$D3=A$1,COUNTIF(Draft_Import!$D$2:'Draft_Import'!$D3,A$1),"") | B3: =IFERROR(INDEX(Draft_Import!$E$2:$E$250,MATCH(ROWS(B$2:B3),A$2:A$250,0)),"") | C3: =IF(Draft_Import!$D3=C$1,COUNTIF(Draft_Import!$D$2:'Draft_Import'!$D3,C$1),"") | D3: =IFERROR(INDEX(Draft_Import!$E$2:$E$250,MATCH(ROWS(D$2:D3),C$2:C$250,0)),"") | E3: =IF(Draft_Import!$D3=E$1,COUNTIF(Draft_Import!$D$2:'Draft_Import'!$D3,E$1),"") | F3: =IFERROR(INDEX(Draft_Import!$E$2:$E$250,MATCH(ROWS(F$2:F3),E$2:E$250,0)),"") | G3: =IF(Draft_Import!$D3=G$1,COUNTIF(Draft_Import!$D$2:'Draft_Import'!$D3,G$1),"") | H3: =IFERROR(INDEX(Draft_Import!$E$2:$E$250,MATCH(ROWS(H$2:H3),G$2:G$250,0)),"") | I3: =IF(Draft_Import!$D3=I$1,COUNTIF(Draft_Import!$D$2:'Draft_Import'!$D3,I$1),"") | J3: =IFERROR(INDEX(Draft_Import!$E$2:$E$250,MATCH(ROWS(J$2:J3),I$2:I$250,0)),"") | K3: =IF(Draft_Import!$D3=K$1,COUNTIF(Draft_Import!$D$2:'Draft_Import'!$D3,K$1),"") | L3: =IFERROR(INDEX(Draft_Import!$E$2:$E$250,MATCH(ROWS(L$2:L3),K$2:K$250,0)),"") | M3: =IF(Draft_Import!$D3=M$1,COUNTIF(Draft_Import!$D$2:'Draft_Import'!$D3,M$1),"") | N3: =IFERROR(INDEX(Draft_Import!$E$2:$E$250,MATCH(ROWS(N$2:N3),M$2:M$250,0)),"") | O3: =IF(Draft_Import!$D3=O$1,COUNTIF(Draft_Import!$D$2:'Draft_Import'!$D3,O$1),"") | P3: =IFERROR(INDEX(Draft_Import!$E$2:$E$250,MATCH(ROWS(P$2:P3),O$2:O$250,0)),"") | Q3: =IF(Draft_Import!$D3=Q$1,COUNTIF(Draft_Import!$D$2:'Draft_Import'!$D3,Q$1),"") | R3: =IFERROR(INDEX(Draft_Import!$E$2:$E$250,MATCH(ROWS(R$2:R3),Q$2:Q$250,0)),"") | S3: =IF(Draft_Import!$D3=S$1,COUNTIF(Draft_Import!$D$2:'Draft_Import'!$D3,S$1),"") | T3: =IFERROR(INDEX(Draft_Import!$E$2:$E$250,MATCH(ROWS(T$2:T3),S$2:S$250,0)),"")
A4: =IF(Draft_Import!$D4=A$1,COUNTIF(Draft_Import!$D$2:'Draft_Import'!$D4,A$1),"") | B4: =IFERROR(INDEX(Draft_Import!$E$2:$E$250,MATCH(ROWS(B$2:B4),A$2:A$250,0)),"") | C4: =IF(Draft_Import!$D4=C$1,COUNTIF(Draft_Import!$D$2:'Draft_Import'!$D4,C$1),"") | D4: =IFERROR(INDEX(Draft_Import!$E$2:$E$250,MATCH(ROWS(D$2:D4),C$2:C$250,0)),"") | E4: =IF(Draft_Import!$D4=E$1,COUNTIF(Draft_Import!$D$2:'Draft_Import'!$D4,E$1),"") | F4: =IFERROR(INDEX(Draft_Import!$E$2:$E$250,MATCH(ROWS(F$2:F4),E$2:E$250,0)),"") | G4: =IF(Draft_Import!$D4=G$1,COUNTIF(Draft_Import!$D$2:'Draft_Import'!$D4,G$1),"") | H4: =IFERROR(INDEX(Draft_Import!$E$2:$E$250,MATCH(ROWS(H$2:H4),G$2:G$250,0)),"") | I4: =IF(Draft_Import!$D4=I$1,COUNTIF(Draft_Import!$D$2:'Draft_Import'!$D4,I$1),"") | J4: =IFERROR(INDEX(Draft_Import!$E$2:$E$250,MATCH(ROWS(J$2:J4),I$2:I$250,0)),"") | K4: =IF(Draft_Import!$D4=K$1,COUNTIF(Draft_Import!$D$2:'Draft_Import'!$D4,K$1),"") | L4: =IFERROR(INDEX(Draft_Import!$E$2:$E$250,MATCH(ROWS(L$2:L4),K$2:K$250,0)),"") | M4: =IF(Draft_Import!$D4=M$1,COUNTIF(Draft_Import!$D$2:'Draft_Import'!$D4,M$1),"") | N4: =IFERROR(INDEX(Draft_Import!$E$2:$E$250,MATCH(ROWS(N$2:N4),M$2:M$250,0)),"") | O4: =IF(Draft_Import!$D4=O$1,COUNTIF(Draft_Import!$D$2:'Draft_Import'!$D4,O$1),"") | P4: =IFERROR(INDEX(Draft_Import!$E$2:$E$250,MATCH(ROWS(P$2:P4),O$2:O$250,0)),"") | Q4: =IF(Draft_Import!$D4=Q$1,COUNTIF(Draft_Import!$D$2:'Draft_Import'!$D4,Q$1),"") | R4: =IFERROR(INDEX(Draft_Import!$E$2:$E$250,MATCH(ROWS(R$2:R4),Q$2:Q$250,0)),"") | S4: =IF(Draft_Import!$D4=S$1,COUNTIF(Draft_Import!$D$2:'Draft_Import'!$D4,S$1),"") | T4: =IFERROR(INDEX(Draft_Import!$E$2:$E$250,MATCH(ROWS(T$2:T4),S$2:S$250,0)),"")
A5: =IF(Draft_Import!$D5=A$1,COUNTIF(Draft_Import!$D$2:'Draft_Import'!$D5,A$1),"") | B5: =IFERROR(INDEX(Draft_Import!$E$2:$E$250,MATCH(ROWS(B$2:B5),A$2:A$250,0)),"") | C5: =IF(Draft_Import!$D5=C$1,COUNTIF(Draft_Import!$D$2:'Draft_Import'!$D5,C$1),"") | D5: =IFERROR(INDEX(Draft_Import!$E$2:$E$250,MATCH(ROWS(D$2:D5),C$2:C$250,0)),"") | E5: =IF(Draft_Import!$D5=E$1,COUNTIF(Draft_Import!$D$2:'Draft_Import'!$D5,E$1),"") | F5: =IFERROR(INDEX(Draft_Import!$E$2:$E$250,MATCH(ROWS(F$2:F5),E$2:E$250,0)),"") | G5: =IF(Draft_Import!$D5=G$1,COUNTIF(Draft_Import!$D$2:'Draft_Import'!$D5,G$1),"") | H5: =IFERROR(INDEX(Draft_Import!$E$2:$E$250,MATCH(ROWS(H$2:H5),G$2:G$250,0)),"") | I5: =IF(Draft_Import!$D5=I$1,COUNTIF(Draft_Import!$D$2:'Draft_Import'!$D5,I$1),"") | J5: =IFERROR(INDEX(Draft_Import!$E$2:$E$250,MATCH(ROWS(J$2:J5),I$2:I$250,0)),"") | K5: =IF(Draft_Import!$D5=K$1,COUNTIF(Draft_Import!$D$2:'Draft_Import'!$D5,K$1),"") | L5: =IFERROR(INDEX(Draft_Import!$E$2:$E$250,MATCH(ROWS(L$2:L5),K$2:K$250,0)),"") | M5: =IF(Draft_Import!$D5=M$1,COUNTIF(Draft_Import!$D$2:'Draft_Import'!$D5,M$1),"") | N5: =IFERROR(INDEX(Draft_Import!$E$2:$E$250,MATCH(ROWS(N$2:N5),M$2:M$250,0)),"") | O5: =IF(Draft_Import!$D5=O$1,COUNTIF(Draft_Import!$D$2:'Draft_Import'!$D5,O$1),"") | P5: =IFERROR(INDEX(Draft_Import!$E$2:$E$250,MATCH(ROWS(P$2:P5),O$2:O$250,0)),"") | Q5: =IF(Draft_Import!$D5=Q$1,COUNTIF(Draft_Import!$D$2:'Draft_Import'!$D5,Q$1),"") | R5: =IFERROR(INDEX(Draft_Import!$E$2:$E$250,MATCH(ROWS(R$2:R5),Q$2:Q$250,0)),"") | S5: =IF(Draft_Import!$D5=S$1,COUNTIF(Draft_Import!$D$2:'Draft_Import'!$D5,S$1),"") | T5: =IFERROR(INDEX(Draft_Import!$E$2:$E$250,MATCH(ROWS(T$2:T5),S$2:S$250,0)),"")
A6: =IF(Draft_Import!$D6=A$1,COUNTIF(Draft_Import!$D$2:'Draft_Import'!$D6,A$1),"") | B6: =IFERROR(INDEX(Draft_Import!$E$2:$E$250,MATCH(ROWS(B$2:B6),A$2:A$250,0)),"") | C6: =IF(Draft_Import!$D6=C$1,COUNTIF(Draft_Import!$D$2:'Draft_Import'!$D6,C$1),"") | D6: =IFERROR(INDEX(Draft_Import!$E$2:$E$250,MATCH(ROWS(D$2:D6),C$2:C$250,0)),"") | E6: =IF(Draft_Import!$D6=E$1,COUNTIF(Draft_Import!$D$2:'Draft_Import'!$D6,E$1),"") | F6: =IFERROR(INDEX(Draft_Import!$E$2:$E$250,MATCH(ROWS(F$2:F6),E$2:E$250,0)),"") | G6: =IF(Draft_Import!$D6=G$1,COUNTIF(Draft_Import!$D$2:'Draft_Import'!$D6,G$1),"") | H6: =IFERROR(INDEX(Draft_Import!$E$2:$E$250,MATCH(ROWS(H$2:H6),G$2:G$250,0)),"") | I6: =IF(Draft_Import!$D6=I$1,COUNTIF(Draft_Import!$D$2:'Draft_Import'!$D6,I$1),"") | J6: =IFERROR(INDEX(Draft_Import!$E$2:$E$250,MATCH(ROWS(J$2:J6),I$2:I$250,0)),"") | K6: =IF(Draft_Import!$D6=K$1,COUNTIF(Draft_Import!$D$2:'Draft_Import'!$D6,K$1),"") | L6: =IFERROR(INDEX(Draft_Import!$E$2:$E$250,MATCH(ROWS(L$2:L6),K$2:K$250,0)),"") | M6: =IF(Draft_Import!$D6=M$1,COUNTIF(Draft_Import!$D$2:'Draft_Import'!$D6,M$1),"") | N6: =IFERROR(INDEX(Draft_Import!$E$2:$E$250,MATCH(ROWS(N$2:N6),M$2:M$250,0)),"") | O6: =IF(Draft_Import!$D6=O$1,COUNTIF(Draft_Import!$D$2:'Draft_Import'!$D6,O$1),"") | P6: =IFERROR(INDEX(Draft_Import!$E$2:$E$250,MATCH(ROWS(P$2:P6),O$2:O$250,0)),"") | Q6: =IF(Draft_Import!$D6=Q$1,COUNTIF(Draft_Import!$D$2:'Draft_Import'!$D6,Q$1),"") | R6: =IFERROR(INDEX(Draft_Import!$E$2:$E$250,MATCH(ROWS(R$2:R6),Q$2:Q$250,0)),"") | S6: =IF(Draft_Import!$D6=S$1,COUNTIF(Draft_Import!$D$2:'Draft_Import'!$D6,S$1),"") | T6: =IFERROR(INDEX(Draft_Import!$E$2:$E$250,MATCH(ROWS(T$2:T6),S$2:S$250,0)),"")
A7: =IF(Draft_Import!$D7=A$1,COUNTIF(Draft_Import!$D$2:'Draft_Import'!$D7,A$1),"") | B7: =IFERROR(INDEX(Draft_Import!$E$2:$E$250,MATCH(ROWS(B$2:B7),A$2:A$250,0)),"") | C7: =IF(Draft_Import!$D7=C$1,COUNTIF(Draft_Import!$D$2:'Draft_Import'!$D7,C$1),"") | D7: =IFERROR(INDEX(Draft_Import!$E$2:$E$250,MATCH(ROWS(D$2:D7),C$2:C$250,0)),"") | E7: =IF(Draft_Import!$D7=E$1,COUNTIF(Draft_Import!$D$2:'Draft_Import'!$D7,E$1),"") | F7: =IFERROR(INDEX(Draft_Import!$E$2:$E$250,MATCH(ROWS(F$2:F7),E$2:E$250,0)),"") | G7: =IF(Draft_Import!$D7=G$1,COUNTIF(Draft_Import!$D$2:'Draft_Import'!$D7,G$1),"") | H7: =IFERROR(INDEX(Draft_Import!$E$2:$E$250,MATCH(ROWS(H$2:H7),G$2:G$250,0)),"") | I7: =IF(Draft_Import!$D7=I$1,COUNTIF(Draft_Import!$D$2:'Draft_Import'!$D7,I$1),"") | J7: =IFERROR(INDEX(Draft_Import!$E$2:$E$250,MATCH(ROWS(J$2:J7),I$2:I$250,0)),"") | K7: =IF(Draft_Import!$D7=K$1,COUNTIF(Draft_Import!$D$2:'Draft_Import'!$D7,K$1),"") | L7: =IFERROR(INDEX(Draft_Import!$E$2:$E$250,MATCH(ROWS(L$2:L7),K$2:K$250,0)),"") | M7: =IF(Draft_Import!$D7=M$1,COUNTIF(Draft_Import!$D$2:'Draft_Import'!$D7,M$1),"") | N7: =IFERROR(INDEX(Draft_Import!$E$2:$E$250,MATCH(ROWS(N$2:N7),M$2:M$250,0)),"") | O7: =IF(Draft_Import!$D7=O$1,COUNTIF(Draft_Import!$D$2:'Draft_Import'!$D7,O$1),"") | P7: =IFERROR(INDEX(Draft_Import!$E$2:$E$250,MATCH(ROWS(P$2:P7),O$2:O$250,0)),"") | Q7: =IF(Draft_Import!$D7=Q$1,COUNTIF(Draft_Import!$D$2:'Draft_Import'!$D7,Q$1),"") | R7: =IFERROR(INDEX(Draft_Import!$E$2:$E$250,MATCH(ROWS(R$2:R7),Q$2:Q$250,0)),"") | S7: =IF(Draft_Import!$D7=S$1,COUNTIF(Draft_Import!$D$2:'Draft_Import'!$D7,S$1),"") | T7: =IFERROR(INDEX(Draft_Import!$E$2:$E$250,MATCH(ROWS(T$2:T7),S$2:S$250,0)),"")
A8: =IF(Draft_Import!$D8=A$1,COUNTIF(Draft_Import!$D$2:'Draft_Import'!$D8,A$1),"") | B8: =IFERROR(INDEX(Draft_Import!$E$2:$E$250,MATCH(ROWS(B$2:B8),A$2:A$250,0)),"") | C8: =IF(Draft_Import!$D8=C$1,COUNTIF(Draft_Import!$D$2:'Draft_Import'!$D8,C$1),"") | D8: =IFERROR(INDEX(Draft_Import!$E$2:$E$250,MATCH(ROWS(D$2:D8),C$2:C$250,0)),"") | E8: =IF(Draft_Import!$D8=E$1,COUNTIF(Draft_Import!$D$2:'Draft_Import'!$D8,E$1),"") | F8: =IFERROR(INDEX(Draft_Import!$E$2:$E$250,MATCH(ROWS(F$2:F8),E$2:E$250,0)),"") | G8: =IF(Draft_Import!$D8=G$1,COUNTIF(Draft_Import!$D$2:'Draft_Import'!$D8,G$1),"") | H8: =IFERROR(INDEX(Draft_Import!$E$2:$E$250,MATCH(ROWS(H$2:H8),G$2:G$250,0)),"") | I8: =IF(Draft_Import!$D8=I$1,COUNTIF(Draft_Import!$D$2:'Draft_Import'!$D8,I$1),"") | J8: =IFERROR(INDEX(Draft_Import!$E$2:$E$250,MATCH(ROWS(J$2:J8),I$2:I$250,0)),"") | K8: =IF(Draft_Import!$D8=K$1,COUNTIF(Draft_Import!$D$2:'Draft_Import'!$D8,K$1),"") | L8: =IFERROR(INDEX(Draft_Import!$E$2:$E$250,MATCH(ROWS(L$2:L8),K$2:K$250,0)),"") | M8: =IF(Draft_Import!$D8=M$1,COUNTIF(Draft_Import!$D$2:'Draft_Import'!$D8,M$1),"") | N8: =IFERROR(INDEX(Draft_Import!$E$2:$E$250,MATCH(ROWS(N$2:N8),M$2:M$250,0)),"") | O8: =IF(Draft_Import!$D8=O$1,COUNTIF(Draft_Import!$D$2:'Draft_Import'!$D8,O$1),"") | P8: =IFERROR(INDEX(Draft_Import!$E$2:$E$250,MATCH(ROWS(P$2:P8),O$2:O$250,0)),"") | Q8: =IF(Draft_Import!$D8=Q$1,COUNTIF(Draft_Import!$D$2:'Draft_Import'!$D8,Q$1),"") | R8: =IFERROR(INDEX(Draft_Import!$E$2:$E$250,MATCH(ROWS(R$2:R8),Q$2:Q$250,0)),"") | S8: =IF(Draft_Import!$D8=S$1,COUNTIF(Draft_Import!$D$2:'Draft_Import'!$D8,S$1),"") | T8: =IFERROR(INDEX(Draft_Import!$E$2:$E$250,MATCH(ROWS(T$2:T8),S$2:S$250,0)),"")
A9: =IF(Draft_Import!$D9=A$1,COUNTIF(Draft_Import!$D$2:'Draft_Import'!$D9,A$1),"") | B9: =IFERROR(INDEX(Draft_Import!$E$2:$E$250,MATCH(ROWS(B$2:B9),A$2:A$250,0)),"") | C9: =IF(Draft_Import!$D9=C$1,COUNTIF(Draft_Import!$D$2:'Draft_Import'!$D9,C$1),"") | D9: =IFERROR(INDEX(Draft_Import!$E$2:$E$250,MATCH(ROWS(D$2:D9),C$2:C$250,0)),"") | E9: =IF(Draft_Import!$D9=E$1,COUNTIF(Draft_Import!$D$2:'Draft_Import'!$D9,E$1),"") | F9: =IFERROR(INDEX(Draft_Import!$E$2:$E$250,MATCH(ROWS(F$2:F9),E$2:E$250,0)),"") | G9: =IF(Draft_Import!$D9=G$1,COUNTIF(Draft_Import!$D$2:'Draft_Import'!$D9,G$1),"") | H9: =IFERROR(INDEX(Draft_Import!$E$2:$E$250,MATCH(ROWS(H$2:H9),G$2:G$250,0)),"") | I9: =IF(Draft_Import!$D9=I$1,COUNTIF(Draft_Import!$D$2:'Draft_Import'!$D9,I$1),"") | J9: =IFERROR(INDEX(Draft_Import!$E$2:$E$250,MATCH(ROWS(J$2:J9),I$2:I$250,0)),"") | K9: =IF(Draft_Import!$D9=K$1,COUNTIF(Draft_Import!$D$2:'Draft_Import'!$D9,K$1),"") | L9: =IFERROR(INDEX(Draft_Import!$E$2:$E$250,MATCH(ROWS(L$2:L9),K$2:K$250,0)),"") | M9: =IF(Draft_Import!$D9=M$1,COUNTIF(Draft_Import!$D$2:'Draft_Import'!$D9,M$1),"") | N9: =IFERROR(INDEX(Draft_Import!$E$2:$E$250,MATCH(ROWS(N$2:N9),M$2:M$250,0)),"") | O9: =IF(Draft_Import!$D9=O$1,COUNTIF(Draft_Import!$D$2:'Draft_Import'!$D9,O$1),"") | P9: =IFERROR(INDEX(Draft_Import!$E$2:$E$250,MATCH(ROWS(P$2:P9),O$2:O$250,0)),"") | Q9: =IF(Draft_Import!$D9=Q$1,COUNTIF(Draft_Import!$D$2:'Draft_Import'!$D9,Q$1),"") | R9: =IFERROR(INDEX(Draft_Import!$E$2:$E$250,MATCH(ROWS(R$2:R9),Q$2:Q$250,0)),"") | S9: =IF(Draft_Import!$D9=S$1,COUNTIF(Draft_Import!$D$2:'Draft_Import'!$D9,S$1),"") | T9: =IFERROR(INDEX(Draft_Import!$E$2:$E$250,MATCH(ROWS(T$2:T9),S$2:S$250,0)),"")
A10: =IF(Draft_Import!$D10=A$1,COUNTIF(Draft_Import!$D$2:'Draft_Import'!$D10,A$1),"") | B10: =IFERROR(INDEX(Draft_Import!$E$2:$E$250,MATCH(ROWS(B$2:B10),A$2:A$250,0)),"") | C10: =IF(Draft_Import!$D10=C$1,COUNTIF(Draft_Import!$D$2:'Draft_Import'!$D10,C$1),"") | D10: =IFERROR(INDEX(Draft_Import!$E$2:$E$250,MATCH(ROWS(D$2:D10),C$2:C$250,0)),"") | E10: =IF(Draft_Import!$D10=E$1,COUNTIF(Draft_Import!$D$2:'Draft_Import'!$D10,E$1),"") | F10: =IFERROR(INDEX(Draft_Import!$E$2:$E$250,MATCH(ROWS(F$2:F10),E$2:E$250,0)),"") | G10: =IF(Draft_Import!$D10=G$1,COUNTIF(Draft_Import!$D$2:'Draft_Import'!$D10,G$1),"") | H10: =IFERROR(INDEX(Draft_Import!$E$2:$E$250,MATCH(ROWS(H$2:H10),G$2:G$250,0)),"") | I10: =IF(Draft_Import!$D10=I$1,COUNTIF(Draft_Import!$D$2:'Draft_Import'!$D10,I$1),"") | J10: =IFERROR(INDEX(Draft_Import!$E$2:$E$250,MATCH(ROWS(J$2:J10),I$2:I$250,0)),"") | K10: =IF(Draft_Import!$D10=K$1,COUNTIF(Draft_Import!$D$2:'Draft_Import'!$D10,K$1),"") | L10: =IFERROR(INDEX(Draft_Import!$E$2:$E$250,MATCH(ROWS(L$2:L10),K$2:K$250,0)),"") | M10: =IF(Draft_Import!$D10=M$1,COUNTIF(Draft_Import!$D$2:'Draft_Import'!$D10,M$1),"") | N10: =IFERROR(INDEX(Draft_Import!$E$2:$E$250,MATCH(ROWS(N$2:N10),M$2:M$250,0)),"") | O10: =IF(Draft_Import!$D10=O$1,COUNTIF(Draft_Import!$D$2:'Draft_Import'!$D10,O$1),"") | P10: =IFERROR(INDEX(Draft_Import!$E$2:$E$250,MATCH(ROWS(P$2:P10),O$2:O$250,0)),"") | Q10: =IF(Draft_Import!$D10=Q$1,COUNTIF(Draft_Import!$D$2:'Draft_Import'!$D10,Q$1),"") | R10: =IFERROR(INDEX(Draft_Import!$E$2:$E$250,MATCH(ROWS(R$2:R10),Q$2:Q$250,0)),"") | S10: =IF(Draft_Import!$D10=S$1,COUNTIF(Draft_Import!$D$2:'Draft_Import'!$D10,S$1),"") | T10: =IFERROR(INDEX(Draft_Import!$E$2:$E$250,MATCH(ROWS(T$2:T10),S$2:S$250,0)),"")
A11: =IF(Draft_Import!$D11=A$1,COUNTIF(Draft_Import!$D$2:'Draft_Import'!$D11,A$1),"") | B11: =IFERROR(INDEX(Draft_Import!$E$2:$E$250,MATCH(ROWS(B$2:B11),A$2:A$250,0)),"") | C11: =IF(Draft_Import!$D11=C$1,COUNTIF(Draft_Import!$D$2:'Draft_Import'!$D11,C$1),"") | D11: =IFERROR(INDEX(Draft_Import!$E$2:$E$250,MATCH(ROWS(D$2:D11),C$2:C$250,0)),"") | E11: =IF(Draft_Import!$D11=E$1,COUNTIF(Draft_Import!$D$2:'Draft_Import'!$D11,E$1),"") | F11: =IFERROR(INDEX(Draft_Import!$E$2:$E$250,MATCH(ROWS(F$2:F11),E$2:E$250,0)),"") | G11: =IF(Draft_Import!$D11=G$1,COUNTIF(Draft_Import!$D$2:'Draft_Import'!$D11,G$1),"") | H11: =IFERROR(INDEX(Draft_Import!$E$2:$E$250,MATCH(ROWS(H$2:H11),G$2:G$250,0)),"") | I11: =IF(Draft_Import!$D11=I$1,COUNTIF(Draft_Import!$D$2:'Draft_Import'!$D11,I$1),"") | J11: =IFERROR(INDEX(Draft_Import!$E$2:$E$250,MATCH(ROWS(J$2:J11),I$2:I$250,0)),"") | K11: =IF(Draft_Import!$D11=K$1,COUNTIF(Draft_Import!$D$2:'Draft_Import'!$D11,K$1),"") | L11: =IFERROR(INDEX(Draft_Import!$E$2:$E$250,MATCH(ROWS(L$2:L11),K$2:K$250,0)),"") | M11: =IF(Draft_Import!$D11=M$1,COUNTIF(Draft_Import!$D$2:'Draft_Import'!$D11,M$1),"") | N11: =IFERROR(INDEX(Draft_Import!$E$2:$E$250,MATCH(ROWS(N$2:N11),M$2:M$250,0)),"") | O11: =IF(Draft_Import!$D11=O$1,COUNTIF(Draft_Import!$D$2:'Draft_Import'!$D11,O$1),"") | P11: =IFERROR(INDEX(Draft_Import!$E$2:$E$250,MATCH(ROWS(P$2:P11),O$2:O$250,0)),"") | Q11: =IF(Draft_Import!$D11=Q$1,COUNTIF(Draft_Import!$D$2:'Draft_Import'!$D11,Q$1),"") | R11: =IFERROR(INDEX(Draft_Import!$E$2:$E$250,MATCH(ROWS(R$2:R11),Q$2:Q$250,0)),"") | S11: =IF(Draft_Import!$D11=S$1,COUNTIF(Draft_Import!$D$2:'Draft_Import'!$D11,S$1),"") | T11: =IFERROR(INDEX(Draft_Import!$E$2:$E$250,MATCH(ROWS(T$2:T11),S$2:S$250,0)),"")
A12: =IF(Draft_Import!$D12=A$1,COUNTIF(Draft_Import!$D$2:'Draft_Import'!$D12,A$1),"") | B12: =IFERROR(INDEX(Draft_Import!$E$2:$E$250,MATCH(ROWS(B$2:B12),A$2:A$250,0)),"") | C12: =IF(Draft_Import!$D12=C$1,COUNTIF(Draft_Import!$D$2:'Draft_Import'!$D12,C$1),"") | D12: =IFERROR(INDEX(Draft_Import!$E$2:$E$250,MATCH(ROWS(D$2:D12),C$2:C$250,0)),"") | E12: =IF(Draft_Import!$D12=E$1,COUNTIF(Draft_Import!$D$2:'Draft_Import'!$D12,E$1),"") | F12: =IFERROR(INDEX(Draft_Import!$E$2:$E$250,MATCH(ROWS(F$2:F12),E$2:E$250,0)),"") | G12: =IF(Draft_Import!$D12=G$1,COUNTIF(Draft_Import!$D$2:'Draft_Import'!$D12,G$1),"") | H12: =IFERROR(INDEX(Draft_Import!$E$2:$E$250,MATCH(ROWS(H$2:H12),G$2:G$250,0)),"") | I12: =IF(Draft_Import!$D12=I$1,COUNTIF(Draft_Import!$D$2:'Draft_Import'!$D12,I$1),"") | J12: =IFERROR(INDEX(Draft_Import!$E$2:$E$250,MATCH(ROWS(J$2:J12),I$2:I$250,0)),"") | K12: =IF(Draft_Import!$D12=K$1,COUNTIF(Draft_Import!$D$2:'Draft_Import'!$D12,K$1),"") | L12: =IFERROR(INDEX(Draft_Import!$E$2:$E$250,MATCH(ROWS(L$2:L12),K$2:K$250,0)),"") | M12: =IF(Draft_Import!$D12=M$1,COUNTIF(Draft_Import!$D$2:'Draft_Import'!$D12,M$1),"") | N12: =IFERROR(INDEX(Draft_Import!$E$2:$E$250,MATCH(ROWS(N$2:N12),M$2:M$250,0)),"") | O12: =IF(Draft_Import!$D12=O$1,COUNTIF(Draft_Import!$D$2:'Draft_Import'!$D12,O$1),"") | P12: =IFERROR(INDEX(Draft_Import!$E$2:$E$250,MATCH(ROWS(P$2:P12),O$2:O$250,0)),"") | Q12: =IF(Draft_Import!$D12=Q$1,COUNTIF(Draft_Import!$D$2:'Draft_Import'!$D12,Q$1),"") | R12: =IFERROR(INDEX(Draft_Import!$E$2:$E$250,MATCH(ROWS(R$2:R12),Q$2:Q$250,0)),"") | S12: =IF(Draft_Import!$D12=S$1,COUNTIF(Draft_Import!$D$2:'Draft_Import'!$D12,S$1),"") | T12: =IFERROR(INDEX(Draft_Import!$E$2:$E$250,MATCH(ROWS(T$2:T12),S$2:S$250,0)),"")
A13: =IF(Draft_Import!$D13=A$1,COUNTIF(Draft_Import!$D$2:'Draft_Import'!$D13,A$1),"") | B13: =IFERROR(INDEX(Draft_Import!$E$2:$E$250,MATCH(ROWS(B$2:B13),A$2:A$250,0)),"") | C13: =IF(Draft_Import!$D13=C$1,COUNTIF(Draft_Import!$D$2:'Draft_Import'!$D13,C$1),"") | D13: =IFERROR(INDEX(Draft_Import!$E$2:$E$250,MATCH(ROWS(D$2:D13),C$2:C$250,0)),"") | E13: =IF(Draft_Import!$D13=E$1,COUNTIF(Draft_Import!$D$2:'Draft_Import'!$D13,E$1),"") | F13: =IFERROR(INDEX(Draft_Import!$E$2:$E$250,MATCH(ROWS(F$2:F13),E$2:E$250,0)),"") | G13: =IF(Draft_Import!$D13=G$1,COUNTIF(Draft_Import!$D$2:'Draft_Import'!$D13,G$1),"") | H13: =IFERROR(INDEX(Draft_Import!$E$2:$E$250,MATCH(ROWS(H$2:H13),G$2:G$250,0)),"") | I13: =IF(Draft_Import!$D13=I$1,COUNTIF(Draft_Import!$D$2:'Draft_Import'!$D13,I$1),"") | J13: =IFERROR(INDEX(Draft_Import!$E$2:$E$250,MATCH(ROWS(J$2:J13),I$2:I$250,0)),"") | K13: =IF(Draft_Import!$D13=K$1,COUNTIF(Draft_Import!$D$2:'Draft_Import'!$D13,K$1),"") | L13: =IFERROR(INDEX(Draft_Import!$E$2:$E$250,MATCH(ROWS(L$2:L13),K$2:K$250,0)),"") | M13: =IF(Draft_Import!$D13=M$1,COUNTIF(Draft_Import!$D$2:'Draft_Import'!$D13,M$1),"") | N13: =IFERROR(INDEX(Draft_Import!$E$2:$E$250,MATCH(ROWS(N$2:N13),M$2:M$250,0)),"") | O13: =IF(Draft_Import!$D13=O$1,COUNTIF(Draft_Import!$D$2:'Draft_Import'!$D13,O$1),"") | P13: =IFERROR(INDEX(Draft_Import!$E$2:$E$250,MATCH(ROWS(P$2:P13),O$2:O$250,0)),"") | Q13: =IF(Draft_Import!$D13=Q$1,COUNTIF(Draft_Import!$D$2:'Draft_Import'!$D13,Q$1),"") | R13: =IFERROR(INDEX(Draft_Import!$E$2:$E$250,MATCH(ROWS(R$2:R13),Q$2:Q$250,0)),"") | S13: =IF(Draft_Import!$D13=S$1,COUNTIF(Draft_Import!$D$2:'Draft_Import'!$D13,S$1),"") | T13: =IFERROR(INDEX(Draft_Import!$E$2:$E$250,MATCH(ROWS(T$2:T13),S$2:S$250,0)),"")
... A21: =IF(Draft_Import!$D21=A$1,COUNTIF(Draft_Import!$D$2:'Draft_Import'!$D21,A$1),"") | B21: =IFERROR(INDEX(Draft_Import!$E$2:$E$250,MATCH(ROWS(B$2:B21),A$2:A$250,0)),"") | C21: =IF(Draft_Import!$D21=C$1,COUNTIF(Draft_Import!$D$2:'Draft_Import'!$D21,C$1),"") | D21: =IFERROR(INDEX(Draft_Import!$E$2:$E$250,MATCH(ROWS(D$2:D21),C$2:C$250,0)),"") | E21: =IF(Draft_Import!$D21=E$1,COUNTIF(Draft_Import!$D$2:'Draft_Import'!$D21,E$1),"") | F21: =IFERROR(INDEX(Draft_Import!$E$2:$E$250,MATCH(ROWS(F$2:F21),E$2:E$250,0)),"") | G21: =IF(Draft_Import!$D21=G$1,COUNTIF(Draft_Import!$D$2:'Draft_Import'!$D21,G$1),"") | H21: =IFERROR(INDEX(Draft_Import!$E$2:$E$250,MATCH(ROWS(H$2:H21),G$2:G$250,0)),"") | I21: =IF(Draft_Import!$D21=I$1,COUNTIF(Draft_Import!$D$2:'Draft_Import'!$D21,I$1),"") | J21: =IFERROR(INDEX(Draft_Import!$E$2:$E$250,MATCH(ROWS(J$2:J21),I$2:I$250,0)),"") | K21: =IF(Draft_Import!$D21=K$1,COUNTIF(Draft_Import!$D$2:'Draft_Import'!$D21,K$1),"") | L21: =IFERROR(INDEX(Draft_Import!$E$2:$E$250,MATCH(ROWS(L$2:L21),K$2:K$250,0)),"") | M21: =IF(Draft_Import!$D21=M$1,COUNTIF(Draft_Import!$D$2:'Draft_Import'!$D21,M$1),"") | N21: =IFERROR(INDEX(Draft_Import!$E$2:$E$250,MATCH(ROWS(N$2:N21),M$2:M$250,0)),"") | O21: =IF(Draft_Import!$D21=O$1,COUNTIF(Draft_Import!$D$2:'Draft_Import'!$D21,O$1),"") | P21: =IFERROR(INDEX(Draft_Import!$E$2:$E$250,MATCH(ROWS(P$2:P21),O$2:O$250,0)),"") | Q21: =IF(Draft_Import!$D21=Q$1,COUNTIF(Draft_Import!$D$2:'Draft_Import'!$D21,Q$1),"") | R21: =IFERROR(INDEX(Draft_Import!$E$2:$E$250,MATCH(ROWS(R$2:R21),Q$2:Q$250,0)),"") | S21: =IF(Draft_Import!$D21=S$1,COUNTIF(Draft_Import!$D$2:'Draft_Import'!$D21,S$1),"") | T21: =IFERROR(INDEX(Draft_Import!$E$2:$E$250,MATCH(ROWS(T$2:T21),S$2:S$250,0)),"")
A22: =IF(Draft_Import!$D22=A$1,COUNTIF(Draft_Import!$D$2:'Draft_Import'!$D22,A$1),"") | C22: =IF(Draft_Import!$D22=C$1,COUNTIF(Draft_Import!$D$2:'Draft_Import'!$D22,C$1),"") | E22: =IF(Draft_Import!$D22=E$1,COUNTIF(Draft_Import!$D$2:'Draft_Import'!$D22,E$1),"") | G22: =IF(Draft_Import!$D22=G$1,COUNTIF(Draft_Import!$D$2:'Draft_Import'!$D22,G$1),"") | I22: =IF(Draft_Import!$D22=I$1,COUNTIF(Draft_Import!$D$2:'Draft_Import'!$D22,I$1),"") | K22: =IF(Draft_Import!$D22=K$1,COUNTIF(Draft_Import!$D$2:'Draft_Import'!$D22,K$1),"") | M22: =IF(Draft_Import!$D22=M$1,COUNTIF(Draft_Import!$D$2:'Draft_Import'!$D22,M$1),"") | O22: =IF(Draft_Import!$D22=O$1,COUNTIF(Draft_Import!$D$2:'Draft_Import'!$D22,O$1),"") | Q22: =IF(Draft_Import!$D22=Q$1,COUNTIF(Draft_Import!$D$2:'Draft_Import'!$D22,Q$1),"") | S22: =IF(Draft_Import!$D22=S$1,COUNTIF(Draft_Import!$D$2:'Draft_Import'!$D22,S$1),"")
A23: =IF(Draft_Import!$D23=A$1,COUNTIF(Draft_Import!$D$2:'Draft_Import'!$D23,A$1),"") | C23: =IF(Draft_Import!$D23=C$1,COUNTIF(Draft_Import!$D$2:'Draft_Import'!$D23,C$1),"") | E23: =IF(Draft_Import!$D23=E$1,COUNTIF(Draft_Import!$D$2:'Draft_Import'!$D23,E$1),"") | G23: =IF(Draft_Import!$D23=G$1,COUNTIF(Draft_Import!$D$2:'Draft_Import'!$D23,G$1),"") | I23: =IF(Draft_Import!$D23=I$1,COUNTIF(Draft_Import!$D$2:'Draft_Import'!$D23,I$1),"") | K23: =IF(Draft_Import!$D23=K$1,COUNTIF(Draft_Import!$D$2:'Draft_Import'!$D23,K$1),"") | M23: =IF(Draft_Import!$D23=M$1,COUNTIF(Draft_Import!$D$2:'Draft_Import'!$D23,M$1),"") | O23: =IF(Draft_Import!$D23=O$1,COUNTIF(Draft_Import!$D$2:'Draft_Import'!$D23,O$1),"") | Q23: =IF(Draft_Import!$D23=Q$1,COUNTIF(Draft_Import!$D$2:'Draft_Import'!$D23,Q$1),"") | S23: =IF(Draft_Import!$D23=S$1,COUNTIF(Draft_Import!$D$2:'Draft_Import'!$D23,S$1),"")
A24: =IF(Draft_Import!$D24=A$1,COUNTIF(Draft_Import!$D$2:'Draft_Import'!$D24,A$1),"") | C24: =IF(Draft_Import!$D24=C$1,COUNTIF(Draft_Import!$D$2:'Draft_Import'!$D24,C$1),"") | E24: =IF(Draft_Import!$D24=E$1,COUNTIF(Draft_Import!$D$2:'Draft_Import'!$D24,E$1),"") | G24: =IF(Draft_Import!$D24=G$1,COUNTIF(Draft_Import!$D$2:'Draft_Import'!$D24,G$1),"") | I24: =IF(Draft_Import!$D24=I$1,COUNTIF(Draft_Import!$D$2:'Draft_Import'!$D24,I$1),"") | K24: =IF(Draft_Import!$D24=K$1,COUNTIF(Draft_Import!$D$2:'Draft_Import'!$D24,K$1),"") | M24: =IF(Draft_Import!$D24=M$1,COUNTIF(Draft_Import!$D$2:'Draft_Import'!$D24,M$1),"") | O24: =IF(Draft_Import!$D24=O$1,COUNTIF(Draft_Import!$D$2:'Draft_Import'!$D24,O$1),"") | Q24: =IF(Draft_Import!$D24=Q$1,COUNTIF(Draft_Import!$D$2:'Draft_Import'!$D24,Q$1),"") | S24: =IF(Draft_Import!$D24=S$1,COUNTIF(Draft_Import!$D$2:'Draft_Import'!$D24,S$1),"")
A25: =IF(Draft_Import!$D25=A$1,COUNTIF(Draft_Import!$D$2:'Draft_Import'!$D25,A$1),"") | C25: =IF(Draft_Import!$D25=C$1,COUNTIF(Draft_Import!$D$2:'Draft_Import'!$D25,C$1),"") | E25: =IF(Draft_Import!$D25=E$1,COUNTIF(Draft_Import!$D$2:'Draft_Import'!$D25,E$1),"") | G25: =IF(Draft_Import!$D25=G$1,COUNTIF(Draft_Import!$D$2:'Draft_Import'!$D25,G$1),"") | I25: =IF(Draft_Import!$D25=I$1,COUNTIF(Draft_Import!$D$2:'Draft_Import'!$D25,I$1),"") | K25: =IF(Draft_Import!$D25=K$1,COUNTIF(Draft_Import!$D$2:'Draft_Import'!$D25,K$1),"") | M25: =IF(Draft_Import!$D25=M$1,COUNTIF(Draft_Import!$D$2:'Draft_Import'!$D25,M$1),"") | O25: =IF(Draft_Import!$D25=O$1,COUNTIF(Draft_Import!$D$2:'Draft_Import'!$D25,O$1),"") | Q25: =IF(Draft_Import!$D25=Q$1,COUNTIF(Draft_Import!$D$2:'Draft_Import'!$D25,Q$1),"") | S25: =IF(Draft_Import!$D25=S$1,COUNTIF(Draft_Import!$D$2:'Draft_Import'!$D25,S$1),"")
A26: =IF(Draft_Import!$D26=A$1,COUNTIF(Draft_Import!$D$2:'Draft_Import'!$D26,A$1),"") | C26: =IF(Draft_Import!$D26=C$1,COUNTIF(Draft_Import!$D$2:'Draft_Import'!$D26,C$1),"") | E26: =IF(Draft_Import!$D26=E$1,COUNTIF(Draft_Import!$D$2:'Draft_Import'!$D26,E$1),"") | G26: =IF(Draft_Import!$D26=G$1,COUNTIF(Draft_Import!$D$2:'Draft_Import'!$D26,G$1),"") | I26: =IF(Draft_Import!$D26=I$1,COUNTIF(Draft_Import!$D$2:'Draft_Import'!$D26,I$1),"") | K26: =IF(Draft_Import!$D26=K$1,COUNTIF(Draft_Import!$D$2:'Draft_Import'!$D26,K$1),"") | M26: =IF(Draft_Import!$D26=M$1,COUNTIF(Draft_Import!$D$2:'Draft_Import'!$D26,M$1),"") | O26: =IF(Draft_Import!$D26=O$1,COUNTIF(Draft_Import!$D$2:'Draft_Import'!$D26,O$1),"") | Q26: =IF(Draft_Import!$D26=Q$1,COUNTIF(Draft_Import!$D$2:'Draft_Import'!$D26,Q$1),"") | S26: =IF(Draft_Import!$D26=S$1,COUNTIF(Draft_Import!$D$2:'Draft_Import'!$D26,S$1),"")
A27: =IF(Draft_Import!$D27=A$1,COUNTIF(Draft_Import!$D$2:'Draft_Import'!$D27,A$1),"") | C27: =IF(Draft_Import!$D27=C$1,COUNTIF(Draft_Import!$D$2:'Draft_Import'!$D27,C$1),"") | E27: =IF(Draft_Import!$D27=E$1,COUNTIF(Draft_Import!$D$2:'Draft_Import'!$D27,E$1),"") | G27: =IF(Draft_Import!$D27=G$1,COUNTIF(Draft_Import!$D$2:'Draft_Import'!$D27,G$1),"") | I27: =IF(Draft_Import!$D27=I$1,COUNTIF(Draft_Import!$D$2:'Draft_Import'!$D27,I$1),"") | K27: =IF(Draft_Import!$D27=K$1,COUNTIF(Draft_Import!$D$2:'Draft_Import'!$D27,K$1),"") | M27: =IF(Draft_Import!$D27=M$1,COUNTIF(Draft_Import!$D$2:'Draft_Import'!$D27,M$1),"") | O27: =IF(Draft_Import!$D27=O$1,COUNTIF(Draft_Import!$D$2:'Draft_Import'!$D27,O$1),"") | Q27: =IF(Draft_Import!$D27=Q$1,COUNTIF(Draft_Import!$D$2:'Draft_Import'!$D27,Q$1),"") | S27: =IF(Draft_Import!$D27=S$1,COUNTIF(Draft_Import!$D$2:'Draft_Import'!$D27,S$1),"")
A28: =IF(Draft_Import!$D28=A$1,COUNTIF(Draft_Import!$D$2:'Draft_Import'!$D28,A$1),"") | C28: =IF(Draft_Import!$D28=C$1,COUNTIF(Draft_Import!$D$2:'Draft_Import'!$D28,C$1),"") | E28: =IF(Draft_Import!$D28=E$1,COUNTIF(Draft_Import!$D$2:'Draft_Import'!$D28,E$1),"") | G28: =IF(Draft_Import!$D28=G$1,COUNTIF(Draft_Import!$D$2:'Draft_Import'!$D28,G$1),"") | I28: =IF(Draft_Import!$D28=I$1,COUNTIF(Draft_Import!$D$2:'Draft_Import'!$D28,I$1),"") | K28: =IF(Draft_Import!$D28=K$1,COUNTIF(Draft_Import!$D$2:'Draft_Import'!$D28,K$1),"") | M28: =IF(Draft_Import!$D28=M$1,COUNTIF(Draft_Import!$D$2:'Draft_Import'!$D28,M$1),"") | O28: =IF(Draft_Import!$D28=O$1,COUNTIF(Draft_Import!$D$2:'Draft_Import'!$D28,O$1),"") | Q28: =IF(Draft_Import!$D28=Q$1,COUNTIF(Draft_Import!$D$2:'Draft_Import'!$D28,Q$1),"") | S28: =IF(Draft_Import!$D28=S$1,COUNTIF(Draft_Import!$D$2:'Draft_Import'!$D28,S$1),"")
A29: =IF(Draft_Import!$D29=A$1,COUNTIF(Draft_Import!$D$2:'Draft_Import'!$D29,A$1),"") | C29: =IF(Draft_Import!$D29=C$1,COUNTIF(Draft_Import!$D$2:'Draft_Import'!$D29,C$1),"") | E29: =IF(Draft_Import!$D29=E$1,COUNTIF(Draft_Import!$D$2:'Draft_Import'!$D29,E$1),"") | G29: =IF(Draft_Import!$D29=G$1,COUNTIF(Draft_Import!$D$2:'Draft_Import'!$D29,G$1),"") | I29: =IF(Draft_Import!$D29=I$1,COUNTIF(Draft_Import!$D$2:'Draft_Import'!$D29,I$1),"") | K29: =IF(Draft_Import!$D29=K$1,COUNTIF(Draft_Import!$D$2:'Draft_Import'!$D29,K$1),"") | M29: =IF(Draft_Import!$D29=M$1,COUNTIF(Draft_Import!$D$2:'Draft_Import'!$D29,M$1),"") | O29: =IF(Draft_Import!$D29=O$1,COUNTIF(Draft_Import!$D$2:'Draft_Import'!$D29,O$1),"") | Q29: =IF(Draft_Import!$D29=Q$1,COUNTIF(Draft_Import!$D$2:'Draft_Import'!$D29,Q$1),"") | S29: =IF(Draft_Import!$D29=S$1,COUNTIF(Draft_Import!$D$2:'Draft_Import'!$D29,S$1),"")
A30: =IF(Draft_Import!$D30=A$1,COUNTIF(Draft_Import!$D$2:'Draft_Import'!$D30,A$1),"") | C30: =IF(Draft_Import!$D30=C$1,COUNTIF(Draft_Import!$D$2:'Draft_Import'!$D30,C$1),"") | E30: =IF(Draft_Import!$D30=E$1,COUNTIF(Draft_Import!$D$2:'Draft_Import'!$D30,E$1),"") | G30: =IF(Draft_Import!$D30=G$1,COUNTIF(Draft_Import!$D$2:'Draft_Import'!$D30,G$1),"") | I30: =IF(Draft_Import!$D30=I$1,COUNTIF(Draft_Import!$D$2:'Draft_Import'!$D30,I$1),"") | K30: =IF(Draft_Import!$D30=K$1,COUNTIF(Draft_Import!$D$2:'Draft_Import'!$D30,K$1),"") | M30: =IF(Draft_Import!$D30=M$1,COUNTIF(Draft_Import!$D$2:'Draft_Import'!$D30,M$1),"") | O30: =IF(Draft_Import!$D30=O$1,COUNTIF(Draft_Import!$D$2:'Draft_Import'!$D30,O$1),"") | Q30: =IF(Draft_Import!$D30=Q$1,COUNTIF(Draft_Import!$D$2:'Draft_Import'!$D30,Q$1),"") | S30: =IF(Draft_Import!$D30=S$1,COUNTIF(Draft_Import!$D$2:'Draft_Import'!$D30,S$1),"")
A31: =IF(Draft_Import!$D31=A$1,COUNTIF(Draft_Import!$D$2:'Draft_Import'!$D31,A$1),"") | C31: =IF(Draft_Import!$D31=C$1,COUNTIF(Draft_Import!$D$2:'Draft_Import'!$D31,C$1),"") | E31: =IF(Draft_Import!$D31=E$1,COUNTIF(Draft_Import!$D$2:'Draft_Import'!$D31,E$1),"") | G31: =IF(Draft_Import!$D31=G$1,COUNTIF(Draft_Import!$D$2:'Draft_Import'!$D31,G$1),"") | I31: =IF(Draft_Import!$D31=I$1,COUNTIF(Draft_Import!$D$2:'Draft_Import'!$D31,I$1),"") | K31: =IF(Draft_Import!$D31=K$1,COUNTIF(Draft_Import!$D$2:'Draft_Import'!$D31,K$1),"") | M31: =IF(Draft_Import!$D31=M$1,COUNTIF(Draft_Import!$D$2:'Draft_Import'!$D31,M$1),"") | O31: =IF(Draft_Import!$D31=O$1,COUNTIF(Draft_Import!$D$2:'Draft_Import'!$D31,O$1),"") | Q31: =IF(Draft_Import!$D31=Q$1,COUNTIF(Draft_Import!$D$2:'Draft_Import'!$D31,Q$1),"") | S31: =IF(Draft_Import!$D31=S$1,COUNTIF(Draft_Import!$D$2:'Draft_Import'!$D31,S$1),"")
A32: =IF(Draft_Import!$D32=A$1,COUNTIF(Draft_Import!$D$2:'Draft_Import'!$D32,A$1),"") | C32: =IF(Draft_Import!$D32=C$1,COUNTIF(Draft_Import!$D$2:'Draft_Import'!$D32,C$1),"") | E32: =IF(Draft_Import!$D32=E$1,COUNTIF(Draft_Import!$D$2:'Draft_Import'!$D32,E$1),"") | G32: =IF(Draft_Import!$D32=G$1,COUNTIF(Draft_Import!$D$2:'Draft_Import'!$D32,G$1),"") | I32: =IF(Draft_Import!$D32=I$1,COUNTIF(Draft_Import!$D$2:'Draft_Import'!$D32,I$1),"") | K32: =IF(Draft_Import!$D32=K$1,COUNTIF(Draft_Import!$D$2:'Draft_Import'!$D32,K$1),"") | M32: =IF(Draft_Import!$D32=M$1,COUNTIF(Draft_Import!$D$2:'Draft_Import'!$D32,M$1),"") | O32: =IF(Draft_Import!$D32=O$1,COUNTIF(Draft_Import!$D$2:'Draft_Import'!$D32,O$1),"") | Q32: =IF(Draft_Import!$D32=Q$1,COUNTIF(Draft_Import!$D$2:'Draft_Import'!$D32,Q$1),"") | S32: =IF(Draft_Import!$D32=S$1,COUNTIF(Draft_Import!$D$2:'Draft_Import'!$D32,S$1),"")
A33: =IF(Draft_Import!$D33=A$1,COUNTIF(Draft_Import!$D$2:'Draft_Import'!$D33,A$1),"") | C33: =IF(Draft_Import!$D33=C$1,COUNTIF(Draft_Import!$D$2:'Draft_Import'!$D33,C$1),"") | E33: =IF(Draft_Import!$D33=E$1,COUNTIF(Draft_Import!$D$2:'Draft_Import'!$D33,E$1),"") | G33: =IF(Draft_Import!$D33=G$1,COUNTIF(Draft_Import!$D$2:'Draft_Import'!$D33,G$1),"") | I33: =IF(Draft_Import!$D33=I$1,COUNTIF(Draft_Import!$D$2:'Draft_Import'!$D33,I$1),"") | K33: =IF(Draft_Import!$D33=K$1,COUNTIF(Draft_Import!$D$2:'Draft_Import'!$D33,K$1),"") | M33: =IF(Draft_Import!$D33=M$1,COUNTIF(Draft_Import!$D$2:'Draft_Import'!$D33,M$1),"") | O33: =IF(Draft_Import!$D33=O$1,COUNTIF(Draft_Import!$D$2:'Draft_Import'!$D33,O$1),"") | Q33: =IF(Draft_Import!$D33=Q$1,COUNTIF(Draft_Import!$D$2:'Draft_Import'!$D33,Q$1),"") | S33: =IF(Draft_Import!$D33=S$1,COUNTIF(Draft_Import!$D$2:'Draft_Import'!$D33,S$1),"")
... A250: =IF(Draft_Import!$D250=A$1,COUNTIF(Draft_Import!$D$2:'Draft_Import'!$D250,A$1),"") | C250: =IF(Draft_Import!$D250=C$1,COUNTIF(Draft_Import!$D$2:'Draft_Import'!$D250,C$1),"") | E250: =IF(Draft_Import!$D250=E$1,COUNTIF(Draft_Import!$D$2:'Draft_Import'!$D250,E$1),"") | G250: =IF(Draft_Import!$D250=G$1,COUNTIF(Draft_Import!$D$2:'Draft_Import'!$D250,G$1),"") | I250: =IF(Draft_Import!$D250=I$1,COUNTIF(Draft_Import!$D$2:'Draft_Import'!$D250,I$1),"") | K250: =IF(Draft_Import!$D250=K$1,COUNTIF(Draft_Import!$D$2:'Draft_Import'!$D250,K$1),"") | M250: =IF(Draft_Import!$D250=M$1,COUNTIF(Draft_Import!$D$2:'Draft_Import'!$D250,M$1),"") | O250: =IF(Draft_Import!$D250=O$1,COUNTIF(Draft_Import!$D$2:'Draft_Import'!$D250,O$1),"") | Q250: =IF(Draft_Import!$D250=Q$1,COUNTIF(Draft_Import!$D$2:'Draft_Import'!$D250,Q$1),"") | S250: =IF(Draft_Import!$D250=S$1,COUNTIF(Draft_Import!$D$2:'Draft_Import'!$D250,S$1),"")

Sheet Team_Scoring
A1: =Draft_Helper!A1 | E1: =Draft_Helper!C1 | I1: =Draft_Helper!E1 | M1: =Draft_Helper!G1 | Q1: =Draft_Helper!I1
A2: Player | B2: Score | C2: Numeric | E2: Player | F2: Score | G2: Numeric | I2: Player | J2: Score | K2: Numeric | M2: Player | N2: Score | O2: Numeric | Q2: Player | R2: Score | S2: Numeric
A3: =Draft_Helper!B2 | B3: =IFERROR(IF(OR(VLOOKUP(A3, Scores!$C$2:$D$459, 2, FALSE)="E", VLOOKUP(A3, Scores!$C$2:$D$459, 2, FALSE)=""), 0, VLOOKUP(A3, Scores!$C$2:$D$459, 2, FALSE)),0) | C3: =IF(B3="","",IF(UPPER(TRIM(SUBSTITUTE(SUBSTITUTE(B3,"(",""),")","")))="E",0,VALUE(TRIM(SUBSTITUTE(SUBSTITUTE(B3,"(",""),")",""))))) | E3: =Draft_Helper!D2 | F3: =IFERROR(IF(OR(VLOOKUP(E3, Scores!$C$2:$D$459, 2, FALSE)="E", VLOOKUP(E3, Scores!$C$2:$D$459, 2, FALSE)=""), 0, VLOOKUP(E3, Scores!$C$2:$D$459, 2, FALSE)),0) | G3: =IF(F3="","",IF(UPPER(TRIM(SUBSTITUTE(SUBSTITUTE(F3,"(",""),")","")))="E",0,VALUE(TRIM(SUBSTITUTE(SUBSTITUTE(F3,"(",""),")",""))))) | I3: =Draft_Helper!F2 | J3: =IFERROR(IF(OR(VLOOKUP(I3, Scores!$C$2:$D$459, 2, FALSE)="E", VLOOKUP(I3, Scores!$C$2:$D$459, 2, FALSE)=""), 0, VLOOKUP(I3, Scores!$C$2:$D$459, 2, FALSE)),0) | K3: =IF(J3="","",IF(UPPER(TRIM(SUBSTITUTE(SUBSTITUTE(J3,"(",""),")","")))="E",0,VALUE(TRIM(SUBSTITUTE(SUBSTITUTE(J3,"(",""),")",""))))) | M3: =Draft_Helper!H2 | N3: =IFERROR(IF(OR(VLOOKUP(M3, Scores!$C$2:$D$459, 2, FALSE)="E", VLOOKUP(M3, Scores!$C$2:$D$459, 2, FALSE)=""), 0, VLOOKUP(M3, Scores!$C$2:$D$459, 2, FALSE)),0) | O3: =IF(N3="","",IF(UPPER(TRIM(SUBSTITUTE(SUBSTITUTE(N3,"(",""),")","")))="E",0,VALUE(TRIM(SUBSTITUTE(SUBSTITUTE(N3,"(",""),")",""))))) | Q3: =Draft_Helper!J2 | R3: =IFERROR(IF(OR(VLOOKUP(Q3, Scores!$C$2:$D$459, 2, FALSE)="E", VLOOKUP(Q3, Scores!$C$2:$D$459, 2, FALSE)=""), 0, VLOOKUP(Q3, Scores!$C$2:$D$459, 2, FALSE)),0) | S3: =IF(R3="","",IF(UPPER(TRIM(SUBSTITUTE(SUBSTITUTE(R3,"(",""),")","")))="E",0,VALUE(TRIM(SUBSTITUTE(SUBSTITUTE(R3,"(",""),")","")))))
A4: =Draft_Helper!B3 | B4: =IFERROR(IF(OR(VLOOKUP(A4, Scores!$C$2:$D$459, 2, FALSE)="E", VLOOKUP(A4, Scores!$C$2:$D$459, 2, FALSE)=""), 0, VLOOKUP(A4, Scores!$C$2:$D$459, 2, FALSE)),0) | C4: =IF(B4="","",IF(UPPER(TRIM(SUBSTITUTE(SUBSTITUTE(B4,"(",""),")","")))="E",0,VALUE(TRIM(SUBSTITUTE(SUBSTITUTE(B4,"(",""),")",""))))) | E4: =Draft_Helper!D3 | F4: =IFERROR(IF(OR(VLOOKUP(E4, Scores!$C$2:$D$459, 2, FALSE)="E", VLOOKUP(E4, Scores!$C$2:$D$459, 2, FALSE)=""), 0, VLOOKUP(E4, Scores!$C$2:$D$459, 2, FALSE)),0) | G4: =IF(F4="","",IF(UPPER(TRIM(SUBSTITUTE(SUBSTITUTE(F4,"(",""),")","")))="E",0,VALUE(TRIM(SUBSTITUTE(SUBSTITUTE(F4,"(",""),")",""))))) | I4: =Draft_Helper!F3 | J4: =IFERROR(IF(OR(VLOOKUP(I4, Scores!$C$2:$D$459, 2, FALSE)="E", VLOOKUP(I4, Scores!$C$2:$D$459, 2, FALSE)=""), 0, VLOOKUP(I4, Scores!$C$2:$D$459, 2, FALSE)),0) | K4: =IF(J4="","",IF(UPPER(TRIM(SUBSTITUTE(SUBSTITUTE(J4,"(",""),")","")))="E",0,VALUE(TRIM(SUBSTITUTE(SUBSTITUTE(J4,"(",""),")",""))))) | M4: =Draft_Helper!H3 | N4: =IFERROR(IF(OR(VLOOKUP(M4, Scores!$C$2:$D$459, 2, FALSE)="E", VLOOKUP(M4, Scores!$C$2:$D$459, 2, FALSE)=""), 0, VLOOKUP(M4, Scores!$C$2:$D$459, 2, FALSE)),0) | O4: =IF(N4="","",IF(UPPER(TRIM(SUBSTITUTE(SUBSTITUTE(N4,"(",""),")","")))="E",0,VALUE(TRIM(SUBSTITUTE(SUBSTITUTE(N4,"(",""),")",""))))) | Q4: =Draft_Helper!J3 | R4: =IFERROR(IF(OR(VLOOKUP(Q4, Scores!$C$2:$D$459, 2, FALSE)="E", VLOOKUP(Q4, Scores!$C$2:$D$459, 2, FALSE)=""), 0, VLOOKUP(Q4, Scores!$C$2:$D$459, 2, FALSE)),0) | S4: =IF(R4="","",IF(UPPER(TRIM(SUBSTITUTE(SUBSTITUTE(R4,"(",""),")","")))="E",0,VALUE(TRIM(SUBSTITUTE(SUBSTITUTE(R4,"(",""),")","")))))
A5: =Draft_Helper!B4 | B5: =IFERROR(IF(OR(VLOOKUP(A5, Scores!$C$2:$D$459, 2, FALSE)="E", VLOOKUP(A5, Scores!$C$2:$D$459, 2, FALSE)=""), 0, VLOOKUP(A5, Scores!$C$2:$D$459, 2, FALSE)),0) | C5: =IF(B5="","",IF(UPPER(TRIM(SUBSTITUTE(SUBSTITUTE(B5,"(",""),")","")))="E",0,VALUE(TRIM(SUBSTITUTE(SUBSTITUTE(B5,"(",""),")",""))))) | E5: =Draft_Helper!D4 | F5: =IFERROR(IF(OR(VLOOKUP(E5, Scores!$C$2:$D$459, 2, FALSE)="E", VLOOKUP(E5, Scores!$C$2:$D$459, 2, FALSE)=""), 0, VLOOKUP(E5, Scores!$C$2:$D$459, 2, FALSE)),0) | G5: =IF(F5="","",IF(UPPER(TRIM(SUBSTITUTE(SUBSTITUTE(F5,"(",""),")","")))="E",0,VALUE(TRIM(SUBSTITUTE(SUBSTITUTE(F5,"(",""),")",""))))) | I5: =Draft_Helper!F4 | J5: =IFERROR(IF(OR(VLOOKUP(I5, Scores!$C$2:$D$459, 2, FALSE)="E", VLOOKUP(I5, Scores!$C$2:$D$459, 2, FALSE)=""), 0, VLOOKUP(I5, Scores!$C$2:$D$459, 2, FALSE)),0) | K5: =IF(J5="","",IF(UPPER(TRIM(SUBSTITUTE(SUBSTITUTE(J5,"(",""),")","")))="E",0,VALUE(TRIM(SUBSTITUTE(SUBSTITUTE(J5,"(",""),")",""))))) | M5: =Draft_Helper!H4 | N5: =IFERROR(IF(OR(VLOOKUP(M5, Scores!$C$2:$D$459, 2, FALSE)="E", VLOOKUP(M5, Scores!$C$2:$D$459, 2, FALSE)=""), 0, VLOOKUP(M5, Scores!$C$2:$D$459, 2, FALSE)),0) | O5: =IF(N5="","",IF(UPPER(TRIM(SUBSTITUTE(SUBSTITUTE(N5,"(",""),")","")))="E",0,VALUE(TRIM(SUBSTITUTE(SUBSTITUTE(N5,"(",""),")",""))))) | Q5: =Draft_Helper!J4 | R5: =IFERROR(IF(OR(VLOOKUP(Q5, Scores!$C$2:$D$459, 2, FALSE)="E", VLOOKUP(Q5, Scores!$C$2:$D$459, 2, FALSE)=""), 0, VLOOKUP(Q5, Scores!$C$2:$D$459, 2, FALSE)),0) | S5: =IF(R5="","",IF(UPPER(TRIM(SUBSTITUTE(SUBSTITUTE(R5,"(",""),")","")))="E",0,VALUE(TRIM(SUBSTITUTE(SUBSTITUTE(R5,"(",""),")","")))))
A6: =Draft_Helper!B5 | B6: =IFERROR(IF(OR(VLOOKUP(A6, Scores!$C$2:$D$459, 2, FALSE)="E", VLOOKUP(A6, Scores!$C$2:$D$459, 2, FALSE)=""), 0, VLOOKUP(A6, Scores!$C$2:$D$459, 2, FALSE)),0) | C6: =IF(B6="","",IF(UPPER(TRIM(SUBSTITUTE(SUBSTITUTE(B6,"(",""),")","")))="E",0,VALUE(TRIM(SUBSTITUTE(SUBSTITUTE(B6,"(",""),")",""))))) | E6: =Draft_Helper!D5 | F6: =IFERROR(IF(OR(VLOOKUP(E6, Scores!$C$2:$D$459, 2, FALSE)="E", VLOOKUP(E6, Scores!$C$2:$D$459, 2, FALSE)=""), 0, VLOOKUP(E6, Scores!$C$2:$D$459, 2, FALSE)),0) | G6: =IF(F6="","",IF(UPPER(TRIM(SUBSTITUTE(SUBSTITUTE(F6,"(",""),")","")))="E",0,VALUE(TRIM(SUBSTITUTE(SUBSTITUTE(F6,"(",""),")",""))))) | I6: =Draft_Helper!F5 | J6: =IFERROR(IF(OR(VLOOKUP(I6, Scores!$C$2:$D$459, 2, FALSE)="E", VLOOKUP(I6, Scores!$C$2:$D$459, 2, FALSE)=""), 0, VLOOKUP(I6, Scores!$C$2:$D$459, 2, FALSE)),0) | K6: =IF(J6="","",IF(UPPER(TRIM(SUBSTITUTE(SUBSTITUTE(J6,"(",""),")","")))="E",0,VALUE(TRIM(SUBSTITUTE(SUBSTITUTE(J6,"(",""),")",""))))) | M6: =Draft_Helper!H5 | N6: =IFERROR(IF(OR(VLOOKUP(M6, Scores!$C$2:$D$459, 2, FALSE)="E", VLOOKUP(M6, Scores!$C$2:$D$459, 2, FALSE)=""), 0, VLOOKUP(M6, Scores!$C$2:$D$459, 2, FALSE)),0) | O6: =IF(N6="","",IF(UPPER(TRIM(SUBSTITUTE(SUBSTITUTE(N6,"(",""),")","")))="E",0,VALUE(TRIM(SUBSTITUTE(SUBSTITUTE(N6,"(",""),")",""))))) | Q6: =Draft_Helper!J5 | R6: =IFERROR(IF(OR(VLOOKUP(Q6, Scores!$C$2:$D$459, 2, FALSE)="E", VLOOKUP(Q6, Scores!$C$2:$D$459, 2, FALSE)=""), 0, VLOOKUP(Q6, Scores!$C$2:$D$459, 2, FALSE)),0) | S6: =IF(R6="","",IF(UPPER(TRIM(SUBSTITUTE(SUBSTITUTE(R6,"(",""),")","")))="E",0,VALUE(TRIM(SUBSTITUTE(SUBSTITUTE(R6,"(",""),")","")))))
A7: =Draft_Helper!B6 | B7: =IFERROR(IF(OR(VLOOKUP(A7, Scores!$C$2:$D$459, 2, FALSE)="E", VLOOKUP(A7, Scores!$C$2:$D$459, 2, FALSE)=""), 0, VLOOKUP(A7, Scores!$C$2:$D$459, 2, FALSE)),0) | C7: =IF(B7="","",IF(UPPER(TRIM(SUBSTITUTE(SUBSTITUTE(B7,"(",""),")","")))="E",0,VALUE(TRIM(SUBSTITUTE(SUBSTITUTE(B7,"(",""),")",""))))) | E7: =Draft_Helper!D6 | F7: =IFERROR(IF(OR(VLOOKUP(E7, Scores!$C$2:$D$459, 2, FALSE)="E", VLOOKUP(E7, Scores!$C$2:$D$459, 2, FALSE)=""), 0, VLOOKUP(E7, Scores!$C$2:$D$459, 2, FALSE)),0) | G7: =IF(F7="","",IF(UPPER(TRIM(SUBSTITUTE(SUBSTITUTE(F7,"(",""),")","")))="E",0,VALUE(TRIM(SUBSTITUTE(SUBSTITUTE(F7,"(",""),")",""))))) | I7: =Draft_Helper!F6 | J7: =IFERROR(IF(OR(VLOOKUP(I7, Scores!$C$2:$D$459, 2, FALSE)="E", VLOOKUP(I7, Scores!$C$2:$D$459, 2, FALSE)=""), 0, VLOOKUP(I7, Scores!$C$2:$D$459, 2, FALSE)),0) | K7: =IF(J7="","",IF(UPPER(TRIM(SUBSTITUTE(SUBSTITUTE(J7,"(",""),")","")))="E",0,VALUE(TRIM(SUBSTITUTE(SUBSTITUTE(J7,"(",""),")",""))))) | M7: =Draft_Helper!H6 | N7: =IFERROR(IF(OR(VLOOKUP(M7, Scores!$C$2:$D$459, 2, FALSE)="E", VLOOKUP(M7, Scores!$C$2:$D$459, 2, FALSE)=""), 0, VLOOKUP(M7, Scores!$C$2:$D$459, 2, FALSE)),0) | O7: =IF(N7="","",IF(UPPER(TRIM(SUBSTITUTE(SUBSTITUTE(N7,"(",""),")","")))="E",0,VALUE(TRIM(SUBSTITUTE(SUBSTITUTE(N7,"(",""),")",""))))) | Q7: =Draft_Helper!J6 | R7: =IFERROR(IF(OR(VLOOKUP(Q7, Scores!$C$2:$D$459, 2, FALSE)="E", VLOOKUP(Q7, Scores!$C$2:$D$459, 2, FALSE)=""), 0, VLOOKUP(Q7, Scores!$C$2:$D$459, 2, FALSE)),0) | S7: =IF(R7="","",IF(UPPER(TRIM(SUBSTITUTE(SUBSTITUTE(R7,"(",""),")","")))="E",0,VALUE(TRIM(SUBSTITUTE(SUBSTITUTE(R7,"(",""),")","")))))
A8: =Draft_Helper!B7 | B8: =IFERROR(IF(OR(VLOOKUP(A8, Scores!$C$2:$D$459, 2, FALSE)="E", VLOOKUP(A8, Scores!$C$2:$D$459, 2, FALSE)=""), 0, VLOOKUP(A8, Scores!$C$2:$D$459, 2, FALSE)),0) | C8: =IF(B8="","",IF(UPPER(TRIM(SUBSTITUTE(SUBSTITUTE(B8,"(",""),")","")))="E",0,VALUE(TRIM(SUBSTITUTE(SUBSTITUTE(B8,"(",""),")",""))))) | E8: =Draft_Helper!D7 | F8: =IFERROR(IF(OR(VLOOKUP(E8, Scores!$C$2:$D$459, 2, FALSE)="E", VLOOKUP(E8, Scores!$C$2:$D$459, 2, FALSE)=""), 0, VLOOKUP(E8, Scores!$C$2:$D$459, 2, FALSE)),0) | G8: =IF(F8="","",IF(UPPER(TRIM(SUBSTITUTE(SUBSTITUTE(F8,"(",""),")","")))="E",0,VALUE(TRIM(SUBSTITUTE(SUBSTITUTE(F8,"(",""),")",""))))) | I8: =Draft_Helper!F7 | J8: =IFERROR(IF(OR(VLOOKUP(I8, Scores!$C$2:$D$459, 2, FALSE)="E", VLOOKUP(I8, Scores!$C$2:$D$459, 2, FALSE)=""), 0, VLOOKUP(I8, Scores!$C$2:$D$459, 2, FALSE)),0) | K8: =IF(J8="","",IF(UPPER(TRIM(SUBSTITUTE(SUBSTITUTE(J8,"(",""),")","")))="E",0,VALUE(TRIM(SUBSTITUTE(SUBSTITUTE(J8,"(",""),")",""))))) | M8: =Draft_Helper!H7 | N8: =IFERROR(IF(OR(VLOOKUP(M8, Scores!$C$2:$D$459, 2, FALSE)="E", VLOOKUP(M8, Scores!$C$2:$D$459, 2, FALSE)=""), 0, VLOOKUP(M8, Scores!$C$2:$D$459, 2, FALSE)),0) | O8: =IF(N8="","",IF(UPPER(TRIM(SUBSTITUTE(SUBSTITUTE(N8,"(",""),")","")))="E",0,VALUE(TRIM(SUBSTITUTE(SUBSTITUTE(N8,"(",""),")",""))))) | Q8: =Draft_Helper!J7 | R8: =IFERROR(IF(OR(VLOOKUP(Q8, Scores!$C$2:$D$459, 2, FALSE)="E", VLOOKUP(Q8, Scores!$C$2:$D$459, 2, FALSE)=""), 0, VLOOKUP(Q8, Scores!$C$2:$D$459, 2, FALSE)),0) | S8: =IF(R8="","",IF(UPPER(TRIM(SUBSTITUTE(SUBSTITUTE(R8,"(",""),")","")))="E",0,VALUE(TRIM(SUBSTITUTE(SUBSTITUTE(R8,"(",""),")","")))))
A9: =Draft_Helper!B8 | B9: =IFERROR(IF(OR(VLOOKUP(A9, Scores!$C$2:$D$459, 2, FALSE)="E", VLOOKUP(A9, Scores!$C$2:$D$459, 2, FALSE)=""), 0, VLOOKUP(A9, Scores!$C$2:$D$459, 2, FALSE)),0) | C9: =IF(B9="","",IF(UPPER(TRIM(SUBSTITUTE(SUBSTITUTE(B9,"(",""),")","")))="E",0,VALUE(TRIM(SUBSTITUTE(SUBSTITUTE(B9,"(",""),")",""))))) | E9: =Draft_Helper!D8 | F9: =IFERROR(IF(OR(VLOOKUP(E9, Scores!$C$2:$D$459, 2, FALSE)="E", VLOOKUP(E9, Scores!$C$2:$D$459, 2, FALSE)=""), 0, VLOOKUP(E9, Scores!$C$2:$D$459, 2, FALSE)),0) | G9: =IF(F9="","",IF(UPPER(TRIM(SUBSTITUTE(SUBSTITUTE(F9,"(",""),")","")))="E",0,VALUE(TRIM(SUBSTITUTE(SUBSTITUTE(F9,"(",""),")",""))))) | I9: =Draft_Helper!F8 | J9: =IFERROR(IF(OR(VLOOKUP(I9, Scores!$C$2:$D$459, 2, FALSE)="E", VLOOKUP(I9, Scores!$C$2:$D$459, 2, FALSE)=""), 0, VLOOKUP(I9, Scores!$C$2:$D$459, 2, FALSE)),0) | K9: =IF(J9="","",IF(UPPER(TRIM(SUBSTITUTE(SUBSTITUTE(J9,"(",""),")","")))="E",0,VALUE(TRIM(SUBSTITUTE(SUBSTITUTE(J9,"(",""),")",""))))) | M9: =Draft_Helper!H8 | N9: =IFERROR(IF(OR(VLOOKUP(M9, Scores!$C$2:$D$459, 2, FALSE)="E", VLOOKUP(M9, Scores!$C$2:$D$459, 2, FALSE)=""), 0, VLOOKUP(M9, Scores!$C$2:$D$459, 2, FALSE)),0) | O9: =IF(N9="","",IF(UPPER(TRIM(SUBSTITUTE(SUBSTITUTE(N9,"(",""),")","")))="E",0,VALUE(TRIM(SUBSTITUTE(SUBSTITUTE(N9,"(",""),")",""))))) | Q9: =Draft_Helper!J8 | R9: =IFERROR(IF(OR(VLOOKUP(Q9, Scores!$C$2:$D$459, 2, FALSE)="E", VLOOKUP(Q9, Scores!$C$2:$D$459, 2, FALSE)=""), 0, VLOOKUP(Q9, Scores!$C$2:$D$459, 2, FALSE)),0) | S9: =IF(R9="","",IF(UPPER(TRIM(SUBSTITUTE(SUBSTITUTE(R9,"(",""),")","")))="E",0,VALUE(TRIM(SUBSTITUTE(SUBSTITUTE(R9,"(",""),")","")))))
A10: =Draft_Helper!B9 | B10: =IFERROR(IF(OR(VLOOKUP(A10, Scores!$C$2:$D$459, 2, FALSE)="E", VLOOKUP(A10, Scores!$C$2:$D$459, 2, FALSE)=""), 0, VLOOKUP(A10, Scores!$C$2:$D$459, 2, FALSE)),0) | C10: =IF(B10="","",IF(UPPER(TRIM(SUBSTITUTE(SUBSTITUTE(B10,"(",""),")","")))="E",0,VALUE(TRIM(SUBSTITUTE(SUBSTITUTE(B10,"(",""),")",""))))) | E10: =Draft_Helper!D9 | F10: =IFERROR(IF(OR(VLOOKUP(E10, Scores!$C$2:$D$459, 2, FALSE)="E", VLOOKUP(E10, Scores!$C$2:$D$459, 2, FALSE)=""), 0, VLOOKUP(E10, Scores!$C$2:$D$459, 2, FALSE)),0) | G10: =IF(F10="","",IF(UPPER(TRIM(SUBSTITUTE(SUBSTITUTE(F10,"(",""),")","")))="E",0,VALUE(TRIM(SUBSTITUTE(SUBSTITUTE(F10,"(",""),")",""))))) | I10: =Draft_Helper!F9 | J10: =IFERROR(IF(OR(VLOOKUP(I10, Scores!$C$2:$D$459, 2, FALSE)="E", VLOOKUP(I10, Scores!$C$2:$D$459, 2, FALSE)=""), 0, VLOOKUP(I10, Scores!$C$2:$D$459, 2, FALSE)),0) | K10: =IF(J10="","",IF(UPPER(TRIM(SUBSTITUTE(SUBSTITUTE(J10,"(",""),")","")))="E",0,VALUE(TRIM(SUBSTITUTE(SUBSTITUTE(J10,"(",""),")",""))))) | M10: =Draft_Helper!H9 | N10: =IFERROR(IF(OR(VLOOKUP(M10, Scores!$C$2:$D$459, 2, FALSE)="E", VLOOKUP(M10, Scores!$C$2:$D$459, 2, FALSE)=""), 0, VLOOKUP(M10, Scores!$C$2:$D$459, 2, FALSE)),0) | O10: =IF(N10="","",IF(UPPER(TRIM(SUBSTITUTE(SUBSTITUTE(N10,"(",""),")","")))="E",0,VALUE(TRIM(SUBSTITUTE(SUBSTITUTE(N10,"(",""),")",""))))) | Q10: =Draft_Helper!J9 | R10: =IFERROR(IF(OR(VLOOKUP(Q10, Scores!$C$2:$D$459, 2, FALSE)="E", VLOOKUP(Q10, Scores!$C$2:$D$459, 2, FALSE)=""), 0, VLOOKUP(Q10, Scores!$C$2:$D$459, 2, FALSE)),0) | S10: =IF(R10="","",IF(UPPER(TRIM(SUBSTITUTE(SUBSTITUTE(R10,"(",""),")","")))="E",0,VALUE(TRIM(SUBSTITUTE(SUBSTITUTE(R10,"(",""),")","")))))
A11: =Draft_Helper!B10 | B11: =IFERROR(IF(OR(VLOOKUP(A11, Scores!$C$2:$D$459, 2, FALSE)="E", VLOOKUP(A11, Scores!$C$2:$D$459, 2, FALSE)=""), 0, VLOOKUP(A11, Scores!$C$2:$D$459, 2, FALSE)),0) | C11: =IF(B11="","",IF(UPPER(TRIM(SUBSTITUTE(SUBSTITUTE(B11,"(",""),")","")))="E",0,VALUE(TRIM(SUBSTITUTE(SUBSTITUTE(B11,"(",""),")",""))))) | E11: =Draft_Helper!D10 | F11: =IFERROR(IF(OR(VLOOKUP(E11, Scores!$C$2:$D$459, 2, FALSE)="E", VLOOKUP(E11, Scores!$C$2:$D$459, 2, FALSE)=""), 0, VLOOKUP(E11, Scores!$C$2:$D$459, 2, FALSE)),0) | G11: =IF(F11="","",IF(UPPER(TRIM(SUBSTITUTE(SUBSTITUTE(F11,"(",""),")","")))="E",0,VALUE(TRIM(SUBSTITUTE(SUBSTITUTE(F11,"(",""),")",""))))) | I11: =Draft_Helper!F10 | J11: =IFERROR(IF(OR(VLOOKUP(I11, Scores!$C$2:$D$459, 2, FALSE)="E", VLOOKUP(I11, Scores!$C$2:$D$459, 2, FALSE)=""), 0, VLOOKUP(I11, Scores!$C$2:$D$459, 2, FALSE)),0) | K11: =IF(J11="","",IF(UPPER(TRIM(SUBSTITUTE(SUBSTITUTE(J11,"(",""),")","")))="E",0,VALUE(TRIM(SUBSTITUTE(SUBSTITUTE(J11,"(",""),")",""))))) | M11: =Draft_Helper!H10 | N11: =IFERROR(IF(OR(VLOOKUP(M11, Scores!$C$2:$D$459, 2, FALSE)="E", VLOOKUP(M11, Scores!$C$2:$D$459, 2, FALSE)=""), 0, VLOOKUP(M11, Scores!$C$2:$D$459, 2, FALSE)),0) | O11: =IF(N11="","",IF(UPPER(TRIM(SUBSTITUTE(SUBSTITUTE(N11,"(",""),")","")))="E",0,VALUE(TRIM(SUBSTITUTE(SUBSTITUTE(N11,"(",""),")",""))))) | Q11: =Draft_Helper!J10 | R11: =IFERROR(IF(OR(VLOOKUP(Q11, Scores!$C$2:$D$459, 2, FALSE)="E", VLOOKUP(Q11, Scores!$C$2:$D$459, 2, FALSE)=""), 0, VLOOKUP(Q11, Scores!$C$2:$D$459, 2, FALSE)),0) | S11: =IF(R11="","",IF(UPPER(TRIM(SUBSTITUTE(SUBSTITUTE(R11,"(",""),")","")))="E",0,VALUE(TRIM(SUBSTITUTE(SUBSTITUTE(R11,"(",""),")","")))))
A12: =Draft_Helper!B11 | C12: =IF(B12="","",IF(UPPER(TRIM(SUBSTITUTE(SUBSTITUTE(B12,"(",""),")","")))="E",0,VALUE(TRIM(SUBSTITUTE(SUBSTITUTE(B12,"(",""),")",""))))) | E12: =Draft_Helper!D11 | G12: =IF(F12="","",IF(UPPER(TRIM(SUBSTITUTE(SUBSTITUTE(F12,"(",""),")","")))="E",0,VALUE(TRIM(SUBSTITUTE(SUBSTITUTE(F12,"(",""),")",""))))) | I12: =Draft_Helper!F11 | K12: =IF(J12="","",IF(UPPER(TRIM(SUBSTITUTE(SUBSTITUTE(J12,"(",""),")","")))="E",0,VALUE(TRIM(SUBSTITUTE(SUBSTITUTE(J12,"(",""),")",""))))) | M12: =Draft_Helper!H11 | O12: =IF(N12="","",IF(UPPER(TRIM(SUBSTITUTE(SUBSTITUTE(N12,"(",""),")","")))="E",0,VALUE(TRIM(SUBSTITUTE(SUBSTITUTE(N12,"(",""),")",""))))) | Q12: =Draft_Helper!J11 | S12: =IF(R12="","",IF(UPPER(TRIM(SUBSTITUTE(SUBSTITUTE(R12,"(",""),")","")))="E",0,VALUE(TRIM(SUBSTITUTE(SUBSTITUTE(R12,"(",""),")","")))))
A13: Best 3 Total | C13: =IF(COUNT(C3:C12)=0,"",SUM(IFERROR(SMALL(C3:C12,1),0),IFERROR(SMALL(C3:C12,2),0),IFERROR(SMALL(C3:C12,3),0))) | E13: Best 3 Total | G13: =IF(COUNT(G3:G12)=0,"",SUM(IFERROR(SMALL(G3:G12,1),0),IFERROR(SMALL(G3:G12,2),0),IFERROR(SMALL(G3:G12,3),0))) | I13: Best 3 Total | K13: =IF(COUNT(K3:K12)=0,"",SUM(IFERROR(SMALL(K3:K12,1),0),IFERROR(SMALL(K3:K12,2),0),IFERROR(SMALL(K3:K12,3),0))) | M13: Best 3 Total | O13: =IF(COUNT(O3:O12)=0,"",SUM(IFERROR(SMALL(O3:O12,1),0),IFERROR(SMALL(O3:O12,2),0),IFERROR(SMALL(O3:O12,3),0))) | Q13: Best 3 Total | S13: =IF(COUNT(S3:S12)=0,"",SUM(IFERROR(SMALL(S3:S12,1),0),IFERROR(SMALL(S3:S12,2),0),IFERROR(SMALL(S3:S12,3),0)))
A16: =Draft_Helper!K1 | E16: =Draft_Helper!M1 | I16: =Draft_Helper!O1 | M16: =Draft_Helper!Q1 | Q16: =Draft_Helper!S1
A17: Player | B17: Score | C17: Numeric | E17: Player | F17: Score | G17: Numeric | I17: Player | J17: Score | K17: Numeric | M17: Player | N17: Score | O17: Numeric | Q17: Player | R17: Score | S17: Numeric
A18: =Draft_Helper!L2 | B18: =IFERROR(IF(OR(VLOOKUP(A18, Scores!$C$2:$D$459, 2, FALSE)="E", VLOOKUP(A18, Scores!$C$2:$D$459, 2, FALSE)=""), 0, VLOOKUP(A18, Scores!$C$2:$D$459, 2, FALSE)),0) | C18: =IF(B18="","",IF(UPPER(TRIM(SUBSTITUTE(SUBSTITUTE(B18,"(",""),")","")))="E",0,VALUE(TRIM(SUBSTITUTE(SUBSTITUTE(B18,"(",""),")",""))))) | E18: =Draft_Helper!N2 | F18: =IFERROR(IF(OR(VLOOKUP(E18, Scores!$C$2:$D$459, 2, FALSE)="E", VLOOKUP(E18, Scores!$C$2:$D$459, 2, FALSE)=""), 0, VLOOKUP(E18, Scores!$C$2:$D$459, 2, FALSE)),0) | G18: =IF(F18="","",IF(UPPER(TRIM(SUBSTITUTE(SUBSTITUTE(F18,"(",""),")","")))="E",0,VALUE(TRIM(SUBSTITUTE(SUBSTITUTE(F18,"(",""),")",""))))) | I18: =Draft_Helper!P2 | J18: =IFERROR(IF(OR(VLOOKUP(I18, Scores!$C$2:$D$459, 2, FALSE)="E", VLOOKUP(I18, Scores!$C$2:$D$459, 2, FALSE)=""), 0, VLOOKUP(I18, Scores!$C$2:$D$459, 2, FALSE)),0) | K18: =IF(J18="","",IF(UPPER(TRIM(SUBSTITUTE(SUBSTITUTE(J18,"(",""),")","")))="E",0,VALUE(TRIM(SUBSTITUTE(SUBSTITUTE(J18,"(",""),")",""))))) | M18: =Draft_Helper!R2 | N18: =IFERROR(IF(OR(VLOOKUP(M18, Scores!$C$2:$D$459, 2, FALSE)="E", VLOOKUP(M18, Scores!$C$2:$D$459, 2, FALSE)=""), 0, VLOOKUP(M18, Scores!$C$2:$D$459, 2, FALSE)),0) | O18: =IF(N18="","",IF(UPPER(TRIM(SUBSTITUTE(SUBSTITUTE(N18,"(",""),")","")))="E",0,VALUE(TRIM(SUBSTITUTE(SUBSTITUTE(N18,"(",""),")",""))))) | Q18: =Draft_Helper!T2 | R18: =IFERROR(IF(OR(VLOOKUP(Q18, Scores!$C$2:$D$459, 2, FALSE)="E", VLOOKUP(Q18, Scores!$C$2:$D$459, 2, FALSE)=""), 0, VLOOKUP(Q18, Scores!$C$2:$D$459, 2, FALSE)),0) | S18: =IF(R18="","",IF(UPPER(TRIM(SUBSTITUTE(SUBSTITUTE(R18,"(",""),")","")))="E",0,VALUE(TRIM(SUBSTITUTE(SUBSTITUTE(R18,"(",""),")","")))))
A19: =Draft_Helper!L3 | B19: =IFERROR(IF(OR(VLOOKUP(A19, Scores!$C$2:$D$459, 2, FALSE)="E", VLOOKUP(A19, Scores!$C$2:$D$459, 2, FALSE)=""), 0, VLOOKUP(A19, Scores!$C$2:$D$459, 2, FALSE)),0) | C19: =IF(B19="","",IF(UPPER(TRIM(SUBSTITUTE(SUBSTITUTE(B19,"(",""),")","")))="E",0,VALUE(TRIM(SUBSTITUTE(SUBSTITUTE(B19,"(",""),")",""))))) | E19: =Draft_Helper!N3 | F19: =IFERROR(IF(OR(VLOOKUP(E19, Scores!$C$2:$D$459, 2, FALSE)="E", VLOOKUP(E19, Scores!$C$2:$D$459, 2, FALSE)=""), 0, VLOOKUP(E19, Scores!$C$2:$D$459, 2, FALSE)),0) | G19: =IF(F19="","",IF(UPPER(TRIM(SUBSTITUTE(SUBSTITUTE(F19,"(",""),")","")))="E",0,VALUE(TRIM(SUBSTITUTE(SUBSTITUTE(F19,"(",""),")",""))))) | I19: =Draft_Helper!P3 | J19: =IFERROR(IF(OR(VLOOKUP(I19, Scores!$C$2:$D$459, 2, FALSE)="E", VLOOKUP(I19, Scores!$C$2:$D$459, 2, FALSE)=""), 0, VLOOKUP(I19, Scores!$C$2:$D$459, 2, FALSE)),0) | K19: =IF(J19="","",IF(UPPER(TRIM(SUBSTITUTE(SUBSTITUTE(J19,"(",""),")","")))="E",0,VALUE(TRIM(SUBSTITUTE(SUBSTITUTE(J19,"(",""),")",""))))) | M19: =Draft_Helper!R3 | N19: =IFERROR(IF(OR(VLOOKUP(M19, Scores!$C$2:$D$459, 2, FALSE)="E", VLOOKUP(M19, Scores!$C$2:$D$459, 2, FALSE)=""), 0, VLOOKUP(M19, Scores!$C$2:$D$459, 2, FALSE)),0) | O19: =IF(N19="","",IF(UPPER(TRIM(SUBSTITUTE(SUBSTITUTE(N19,"(",""),")","")))="E",0,VALUE(TRIM(SUBSTITUTE(SUBSTITUTE(N19,"(",""),")",""))))) | Q19: =Draft_Helper!T3 | R19: =IFERROR(IF(OR(VLOOKUP(Q19, Scores!$C$2:$D$459, 2, FALSE)="E", VLOOKUP(Q19, Scores!$C$2:$D$459, 2, FALSE)=""), 0, VLOOKUP(Q19, Scores!$C$2:$D$459, 2, FALSE)),0) | S19: =IF(R19="","",IF(UPPER(TRIM(SUBSTITUTE(SUBSTITUTE(R19,"(",""),")","")))="E",0,VALUE(TRIM(SUBSTITUTE(SUBSTITUTE(R19,"(",""),")","")))))
A20: =Draft_Helper!L4 | B20: =IFERROR(IF(OR(VLOOKUP(A20, Scores!$C$2:$D$459, 2, FALSE)="E", VLOOKUP(A20, Scores!$C$2:$D$459, 2, FALSE)=""), 0, VLOOKUP(A20, Scores!$C$2:$D$459, 2, FALSE)),0) | C20: =IF(B20="","",IF(UPPER(TRIM(SUBSTITUTE(SUBSTITUTE(B20,"(",""),")","")))="E",0,VALUE(TRIM(SUBSTITUTE(SUBSTITUTE(B20,"(",""),")",""))))) | E20: =Draft_Helper!N4 | F20: =IFERROR(IF(OR(VLOOKUP(E20, Scores!$C$2:$D$459, 2, FALSE)="E", VLOOKUP(E20, Scores!$C$2:$D$459, 2, FALSE)=""), 0, VLOOKUP(E20, Scores!$C$2:$D$459, 2, FALSE)),0) | G20: =IF(F20="","",IF(UPPER(TRIM(SUBSTITUTE(SUBSTITUTE(F20,"(",""),")","")))="E",0,VALUE(TRIM(SUBSTITUTE(SUBSTITUTE(F20,"(",""),")",""))))) | I20: =Draft_Helper!P4 | J20: =IFERROR(IF(OR(VLOOKUP(I20, Scores!$C$2:$D$459, 2, FALSE)="E", VLOOKUP(I20, Scores!$C$2:$D$459, 2, FALSE)=""), 0, VLOOKUP(I20, Scores!$C$2:$D$459, 2, FALSE)),0) | K20: =IF(J20="","",IF(UPPER(TRIM(SUBSTITUTE(SUBSTITUTE(J20,"(",""),")","")))="E",0,VALUE(TRIM(SUBSTITUTE(SUBSTITUTE(J20,"(",""),")",""))))) | M20: =Draft_Helper!R4 | N20: =IFERROR(IF(OR(VLOOKUP(M20, Scores!$C$2:$D$459, 2, FALSE)="E", VLOOKUP(M20, Scores!$C$2:$D$459, 2, FALSE)=""), 0, VLOOKUP(M20, Scores!$C$2:$D$459, 2, FALSE)),0) | O20: =IF(N20="","",IF(UPPER(TRIM(SUBSTITUTE(SUBSTITUTE(N20,"(",""),")","")))="E",0,VALUE(TRIM(SUBSTITUTE(SUBSTITUTE(N20,"(",""),")",""))))) | Q20: =Draft_Helper!T4 | R20: =IFERROR(IF(OR(VLOOKUP(Q20, Scores!$C$2:$D$459, 2, FALSE)="E", VLOOKUP(Q20, Scores!$C$2:$D$459, 2, FALSE)=""), 0, VLOOKUP(Q20, Scores!$C$2:$D$459, 2, FALSE)),0) | S20: =IF(R20="","",IF(UPPER(TRIM(SUBSTITUTE(SUBSTITUTE(R20,"(",""),")","")))="E",0,VALUE(TRIM(SUBSTITUTE(SUBSTITUTE(R20,"(",""),")","")))))
A21: =Draft_Helper!L5 | B21: =IFERROR(IF(OR(VLOOKUP(A21, Scores!$C$2:$D$459, 2, FALSE)="E", VLOOKUP(A21, Scores!$C$2:$D$459, 2, FALSE)=""), 0, VLOOKUP(A21, Scores!$C$2:$D$459, 2, FALSE)),0) | C21: =IF(B21="","",IF(UPPER(TRIM(SUBSTITUTE(SUBSTITUTE(B21,"(",""),")","")))="E",0,VALUE(TRIM(SUBSTITUTE(SUBSTITUTE(B21,"(",""),")",""))))) | E21: =Draft_Helper!N5 | F21: =IFERROR(IF(OR(VLOOKUP(E21, Scores!$C$2:$D$459, 2, FALSE)="E", VLOOKUP(E21, Scores!$C$2:$D$459, 2, FALSE)=""), 0, VLOOKUP(E21, Scores!$C$2:$D$459, 2, FALSE)),0) | G21: =IF(F21="","",IF(UPPER(TRIM(SUBSTITUTE(SUBSTITUTE(F21,"(",""),")","")))="E",0,VALUE(TRIM(SUBSTITUTE(SUBSTITUTE(F21,"(",""),")",""))))) | I21: =Draft_Helper!P5 | J21: =IFERROR(IF(OR(VLOOKUP(I21, Scores!$C$2:$D$459, 2, FALSE)="E", VLOOKUP(I21, Scores!$C$2:$D$459, 2, FALSE)=""), 0, VLOOKUP(I21, Scores!$C$2:$D$459, 2, FALSE)),0) | K21: =IF(J21="","",IF(UPPER(TRIM(SUBSTITUTE(SUBSTITUTE(J21,"(",""),")","")))="E",0,VALUE(TRIM(SUBSTITUTE(SUBSTITUTE(J21,"(",""),")",""))))) | M21: =Draft_Helper!R5 | N21: =IFERROR(IF(OR(VLOOKUP(M21, Scores!$C$2:$D$459, 2, FALSE)="E", VLOOKUP(M21, Scores!$C$2:$D$459, 2, FALSE)=""), 0, VLOOKUP(M21, Scores!$C$2:$D$459, 2, FALSE)),0) | O21: =IF(N21="","",IF(UPPER(TRIM(SUBSTITUTE(SUBSTITUTE(N21,"(",""),")","")))="E",0,VALUE(TRIM(SUBSTITUTE(SUBSTITUTE(N21,"(",""),")",""))))) | Q21: =Draft_Helper!T5 | R21: =IFERROR(IF(OR(VLOOKUP(Q21, Scores!$C$2:$D$459, 2, FALSE)="E", VLOOKUP(Q21, Scores!$C$2:$D$459, 2, FALSE)=""), 0, VLOOKUP(Q21, Scores!$C$2:$D$459, 2, FALSE)),0) | S21: =IF(R21="","",IF(UPPER(TRIM(SUBSTITUTE(SUBSTITUTE(R21,"(",""),")","")))="E",0,VALUE(TRIM(SUBSTITUTE(SUBSTITUTE(R21,"(",""),")","")))))
